{size:[27,28,32],palette:[{Name:"ae2:smooth_sky_stone_wall"},{Name:"minecraft:end_rod",Properties:{"facing":"down"}},{Name:"ae2:quartz_fixture",Properties:{"facing":"up"}},{Name:"data_energistics:data_framework"},{Name:"minecraft:smooth_quartz"},{Name:"data_energistics:data_meteorite_2"},{Name:"ae2:smooth_sky_stone_block"},{Name:"ae2:not_so_mysterious_cube"},{Name:"ae2:spatial_pylon"},{Name:"minecraft:end_rod",Properties:{"facing":"up"}},{Name:"data_energistics:data_meteorite_0"},{Name:"data_energistics:data_meteorite_1"},{Name:"minecraft:sea_lantern"},{Name:"ae2:controller"},{Name:"ae2:smooth_sky_stone_slab"},{Name:"ae2:fluix_block"},{Name:"ae2:cut_quartz_wall"},{Name:"minecraft:smooth_quartz_slab"},{Name:"data_energistics:me_digital_storage_core_1k"},{Name:"minecraft:smooth_quartz_stairs",Properties:{"facing":"north"}},{Name:"ae2:fluix_wall"},{Name:"ae2:cut_quartz_block"},{Name:"ae2:energy_acceptor"},{Name:"ae2:cable_bus"},{Name:"ae2:quartz_vibrant_glass"},{Name:"minecraft:glass"},{Name:"minecraft:quartz_slab"},{Name:"data_energistics:trinity_data_core",Properties:{"facing":"north"}},{Name:"ae2:chiseled_quartz_wall"}],blocks:[{pos:[14,5,31],state:0},{pos:[12,5,31],state:0},{pos:[14,6,31],state:0},{pos:[12,6,31],state:0},{pos:[14,7,31],state:0},{pos:[12,7,31],state:0},{pos:[14,8,31],state:0},{pos:[12,8,31],state:0},{pos:[14,9,31],state:0},{pos:[12,9,31],state:0},{pos:[14,10,31],state:0},{pos:[12,10,31],state:0},{pos:[14,11,31],state:0},{pos:[12,11,31],state:0},{pos:[14,12,31],state:0},{pos:[12,12,31],state:0},{pos:[14,13,31],state:0},{pos:[12,13,31],state:0},{pos:[14,14,31],state:1},{pos:[12,14,31],state:1},{pos:[14,15,31],state:2},{pos:[12,15,31],state:2},{pos:[16,0,30],state:3},{pos:[15,0,30],state:3},{pos:[14,0,30],state:3},{pos:[13,0,30],state:3},{pos:[12,0,30],state:3},{pos:[11,0,30],state:3},{pos:[10,0,30],state:3},{pos:[14,3,30],state:0},{pos:[12,3,30],state:0},{pos:[14,4,30],state:0},{pos:[12,4,30],state:0},{pos:[14,5,30],state:4},{pos:[12,5,30],state:4},{pos:[14,6,30],state:4},{pos:[12,6,30],state:4},{pos:[14,7,30],state:4},{pos:[12,7,30],state:4},{pos:[14,8,30],state:4},{pos:[12,8,30],state:4},{pos:[14,9,30],state:4},{pos:[12,9,30],state:4},{pos:[14,10,30],state:4},{pos:[12,10,30],state:4},{pos:[14,11,30],state:4},{pos:[12,11,30],state:4},{pos:[14,12,30],state:4},{pos:[12,12,30],state:4},{pos:[14,13,30],state:4},{pos:[12,13,30],state:4},{pos:[14,14,30],state:5},{pos:[12,14,30],state:5},{pos:[22,0,29],state:3},{pos:[21,0,29],state:3},{pos:[20,0,29],state:3},{pos:[19,0,29],state:3},{pos:[18,0,29],state:3},{pos:[17,0,29],state:3},{pos:[16,0,29],state:3},{pos:[15,0,29],state:6},{pos:[14,0,29],state:6},{pos:[13,0,29],state:6},{pos:[12,0,29],state:6},{pos:[11,0,29],state:6},{pos:[10,0,29],state:3},{pos:[9,0,29],state:3},{pos:[8,0,29],state:3},{pos:[7,0,29],state:3},{pos:[6,0,29],state:3},{pos:[5,0,29],state:3},{pos:[4,0,29],state:3},{pos:[14,1,29],state:6},{pos:[12,1,29],state:6},{pos:[14,2,29],state:0},{pos:[12,2,29],state:0},{pos:[14,3,29],state:4},{pos:[12,3,29],state:4},{pos:[14,4,29],state:4},{pos:[12,4,29],state:4},{pos:[14,5,29],state:4},{pos:[12,5,29],state:4},{pos:[14,6,29],state:4},{pos:[12,6,29],state:4},{pos:[14,7,29],state:4},{pos:[12,7,29],state:4},{pos:[23,0,28],state:3},{pos:[22,0,28],state:3},{pos:[21,0,28],state:7},{pos:[20,0,28],state:6},{pos:[19,0,28],state:6},{pos:[18,0,28],state:6},{pos:[17,0,28],state:6},{pos:[16,0,28],state:7},{pos:[15,0,28],state:6},{pos:[14,0,28],state:6},{pos:[13,0,28],state:6},{pos:[12,0,28],state:6},{pos:[11,0,28],state:6},{pos:[10,0,28],state:7},{pos:[9,0,28],state:6},{pos:[8,0,28],state:6},{pos:[7,0,28],state:6},{pos:[6,0,28],state:6},{pos:[5,0,28],state:7},{pos:[4,0,28],state:3},{pos:[3,0,28],state:3},{pos:[14,1,28],state:8},{pos:[12,1,28],state:8},{pos:[14,2,28],state:4},{pos:[12,2,28],state:4},{pos:[14,3,28],state:4},{pos:[12,3,28],state:4},{pos:[14,4,28],state:4},{pos:[12,4,28],state:4},{pos:[14,5,28],state:4},{pos:[12,5,28],state:4},{pos:[13,13,28],state:6},{pos:[13,14,28],state:6},{pos:[13,15,28],state:6},{pos:[13,16,28],state:6},{pos:[13,17,28],state:6},{pos:[13,18,28],state:6},{pos:[13,19,28],state:6},{pos:[23,0,27],state:3},{pos:[22,0,27],state:6},{pos:[21,0,27],state:6},{pos:[20,0,27],state:3},{pos:[19,0,27],state:3},{pos:[18,0,27],state:3},{pos:[17,0,27],state:3},{pos:[16,0,27],state:6},{pos:[15,0,27],state:6},{pos:[14,0,27],state:6},{pos:[13,0,27],state:6},{pos:[12,0,27],state:6},{pos:[11,0,27],state:6},{pos:[10,0,27],state:6},{pos:[9,0,27],state:3},{pos:[8,0,27],state:3},{pos:[7,0,27],state:3},{pos:[6,0,27],state:3},{pos:[5,0,27],state:6},{pos:[4,0,27],state:6},{pos:[3,0,27],state:3},{pos:[23,1,27],state:0},{pos:[14,1,27],state:8},{pos:[12,1,27],state:8},{pos:[3,1,27],state:0},{pos:[14,2,27],state:4},{pos:[12,2,27],state:4},{pos:[14,3,27],state:4},{pos:[12,3,27],state:4},{pos:[13,11,27],state:6},{pos:[13,12,27],state:6},{pos:[13,13,27],state:4},{pos:[13,14,27],state:4},{pos:[13,15,27],state:4},{pos:[13,16,27],state:4},{pos:[13,17,27],state:4},{pos:[13,18,27],state:4},{pos:[13,19,27],state:4},{pos:[13,20,27],state:6},{pos:[13,21,27],state:6},{pos:[23,0,26],state:3},{pos:[22,0,26],state:6},{pos:[21,0,26],state:6},{pos:[20,0,26],state:3},{pos:[19,0,26],state:3},{pos:[18,0,26],state:3},{pos:[17,0,26],state:3},{pos:[16,0,26],state:6},{pos:[15,0,26],state:6},{pos:[14,0,26],state:6},{pos:[13,0,26],state:6},{pos:[12,0,26],state:6},{pos:[11,0,26],state:6},{pos:[10,0,26],state:6},{pos:[9,0,26],state:3},{pos:[8,0,26],state:3},{pos:[7,0,26],state:3},{pos:[6,0,26],state:3},{pos:[5,0,26],state:6},{pos:[4,0,26],state:6},{pos:[3,0,26],state:3},{pos:[14,1,26],state:8},{pos:[12,1,26],state:8},{pos:[14,2,26],state:4},{pos:[12,2,26],state:4},{pos:[14,3,26],state:8},{pos:[12,3,26],state:8},{pos:[13,9,26],state:6},{pos:[13,10,26],state:6},{pos:[13,11,26],state:4},{pos:[13,12,26],state:4},{pos:[13,13,26],state:0},{pos:[13,14,26],state:0},{pos:[13,15,26],state:0},{pos:[13,16,26],state:9},{pos:[13,17,26],state:1},{pos:[13,18,26],state:9},{pos:[13,19,26],state:1},{pos:[13,20,26],state:4},{pos:[13,21,26],state:4},{pos:[13,22,26],state:6},{pos:[13,23,26],state:6},{pos:[15,26,26],state:10},{pos:[14,26,26],state:10},{pos:[13,26,26],state:10},{pos:[12,26,26],state:10},{pos:[11,26,26],state:10},{pos:[23,0,25],state:3},{pos:[22,0,25],state:6},{pos:[21,0,25],state:6},{pos:[20,0,25],state:3},{pos:[19,0,25],state:3},{pos:[18,0,25],state:3},{pos:[17,0,25],state:3},{pos:[16,0,25],state:6},{pos:[15,0,25],state:6},{pos:[14,0,25],state:6},{pos:[13,0,25],state:6},{pos:[12,0,25],state:6},{pos:[11,0,25],state:6},{pos:[10,0,25],state:6},{pos:[9,0,25],state:3},{pos:[8,0,25],state:3},{pos:[7,0,25],state:3},{pos:[6,0,25],state:3},{pos:[5,0,25],state:6},{pos:[4,0,25],state:6},{pos:[3,0,25],state:3},{pos:[14,1,25],state:8},{pos:[12,1,25],state:8},{pos:[14,2,25],state:4},{pos:[12,2,25],state:4},{pos:[14,3,25],state:8},{pos:[12,3,25],state:8},{pos:[13,8,25],state:6},{pos:[14,9,25],state:6},{pos:[13,9,25],state:4},{pos:[12,9,25],state:6},{pos:[14,10,25],state:6},{pos:[13,10,25],state:4},{pos:[12,10,25],state:6},{pos:[13,14,25],state:0},{pos:[13,15,25],state:0},{pos:[13,16,25],state:0},{pos:[13,22,25],state:4},{pos:[13,23,25],state:4},{pos:[13,24,25],state:6},{pos:[18,25,25],state:11},{pos:[17,25,25],state:11},{pos:[16,25,25],state:11},{pos:[10,25,25],state:11},{pos:[9,25,25],state:11},{pos:[8,25,25],state:11},{pos:[23,0,24],state:3},{pos:[22,0,24],state:6},{pos:[21,0,24],state:6},{pos:[20,0,24],state:3},{pos:[19,0,24],state:3},{pos:[18,0,24],state:3},{pos:[17,0,24],state:3},{pos:[16,0,24],state:6},{pos:[15,0,24],state:6},{pos:[14,0,24],state:6},{pos:[13,0,24],state:12},{pos:[12,0,24],state:6},{pos:[11,0,24],state:6},{pos:[10,0,24],state:6},{pos:[9,0,24],state:3},{pos:[8,0,24],state:3},{pos:[7,0,24],state:3},{pos:[6,0,24],state:3},{pos:[5,0,24],state:6},{pos:[4,0,24],state:6},{pos:[3,0,24],state:3},{pos:[14,1,24],state:8},{pos:[12,1,24],state:8},{pos:[14,2,24],state:4},{pos:[12,2,24],state:4},{pos:[14,3,24],state:8},{pos:[12,3,24],state:8},{pos:[13,7,24],state:6},{pos:[14,8,24],state:6},{pos:[13,8,24],state:4},{pos:[12,8,24],state:6},{pos:[13,9,24],state:0},{pos:[13,10,24],state:0},{pos:[13,15,24],state:0},{pos:[13,16,24],state:0},{pos:[21,24,24],state:5},{pos:[20,24,24],state:5},{pos:[19,24,24],state:5},{pos:[13,24,24],state:4},{pos:[7,24,24],state:5},{pos:[6,24,24],state:5},{pos:[5,24,24],state:5},{pos:[13,25,24],state:6},{pos:[23,0,23],state:3},{pos:[22,0,23],state:6},{pos:[21,0,23],state:7},{pos:[19,0,23],state:3},{pos:[18,0,23],state:3},{pos:[16,0,23],state:7},{pos:[15,0,23],state:6},{pos:[13,0,23],state:6},{pos:[11,0,23],state:6},{pos:[10,0,23],state:7},{pos:[8,0,23],state:3},{pos:[7,0,23],state:3},{pos:[5,0,23],state:7},{pos:[4,0,23],state:6},{pos:[3,0,23],state:3},{pos:[20,1,23],state:6},{pos:[17,1,23],state:6},{pos:[14,1,23],state:8},{pos:[13,1,23],state:13},{pos:[12,1,23],state:8},{pos:[9,1,23],state:6},{pos:[6,1,23],state:6},{pos:[20,2,23],state:6},{pos:[17,2,23],state:6},{pos:[14,2,23],state:4},{pos:[12,2,23],state:4},{pos:[9,2,23],state:6},{pos:[6,2,23],state:6},{pos:[20,3,23],state:6},{pos:[17,3,23],state:6},{pos:[14,3,23],state:8},{pos:[12,3,23],state:8},{pos:[9,3,23],state:6},{pos:[6,3,23],state:6},{pos:[20,4,23],state:4},{pos:[19,4,23],state:4},{pos:[18,4,23],state:4},{pos:[17,4,23],state:4},{pos:[9,4,23],state:4},{pos:[8,4,23],state:4},{pos:[7,4,23],state:4},{pos:[6,4,23],state:4},{pos:[20,5,23],state:14},{pos:[19,5,23],state:14},{pos:[18,5,23],state:14},{pos:[17,5,23],state:14},{pos:[14,5,23],state:15},{pos:[12,5,23],state:15},{pos:[9,5,23],state:14},{pos:[8,5,23],state:14},{pos:[7,5,23],state:14},{pos:[6,5,23],state:14},{pos:[14,6,23],state:15},{pos:[13,6,23],state:6},{pos:[12,6,23],state:15},{pos:[14,7,23],state:6},{pos:[13,7,23],state:4},{pos:[12,7,23],state:6},{pos:[13,8,23],state:0},{pos:[13,9,23],state:0},{pos:[13,10,23],state:6},{pos:[13,11,23],state:6},{pos:[14,14,23],state:4},{pos:[13,14,23],state:6},{pos:[12,14,23],state:4},{pos:[15,15,23],state:4},{pos:[14,15,23],state:4},{pos:[13,15,23],state:6},{pos:[12,15,23],state:4},{pos:[11,15,23],state:4},{pos:[15,16,23],state:16},{pos:[14,16,23],state:4},{pos:[13,16,23],state:6},{pos:[12,16,23],state:4},{pos:[11,16,23],state:16},{pos:[15,17,23],state:4},{pos:[14,17,23],state:4},{pos:[13,17,23],state:12},{pos:[12,17,23],state:4},{pos:[11,17,23],state:4},{pos:[14,18,23],state:4},{pos:[12,18,23],state:4},{pos:[22,23,23],state:5},{pos:[4,23,23],state:5},{pos:[13,25,23],state:4},{pos:[13,26,23],state:6},{pos:[23,0,22],state:3},{pos:[22,0,22],state:6},{pos:[21,0,22],state:6},{pos:[19,0,22],state:3},{pos:[18,0,22],state:3},{pos:[16,0,22],state:6},{pos:[10,0,22],state:6},{pos:[8,0,22],state:3},{pos:[7,0,22],state:3},{pos:[5,0,22],state:6},{pos:[4,0,22],state:6},{pos:[3,0,22],state:3},{pos:[20,1,22],state:6},{pos:[19,1,22],state:3},{pos:[18,1,22],state:3},{pos:[17,1,22],state:6},{pos:[15,1,22],state:4},{pos:[14,1,22],state:4},{pos:[13,1,22],state:13},{pos:[12,1,22],state:4},{pos:[11,1,22],state:4},{pos:[9,1,22],state:6},{pos:[8,1,22],state:3},{pos:[7,1,22],state:3},{pos:[6,1,22],state:6},{pos:[20,2,22],state:4},{pos:[19,2,22],state:17},{pos:[18,2,22],state:17},{pos:[17,2,22],state:4},{pos:[15,2,22],state:4},{pos:[14,2,22],state:4},{pos:[13,2,22],state:13},{pos:[12,2,22],state:4},{pos:[11,2,22],state:4},{pos:[9,2,22],state:4},{pos:[8,2,22],state:17},{pos:[7,2,22],state:17},{pos:[6,2,22],state:4},{pos:[20,3,22],state:4},{pos:[19,3,22],state:17},{pos:[18,3,22],state:17},{pos:[17,3,22],state:4},{pos:[14,3,22],state:15},{pos:[13,3,22],state:13},{pos:[12,3,22],state:15},{pos:[9,3,22],state:4},{pos:[8,3,22],state:17},{pos:[7,3,22],state:17},{pos:[6,3,22],state:4},{pos:[20,4,22],state:4},{pos:[19,4,22],state:17},{pos:[18,4,22],state:17},{pos:[17,4,22],state:4},{pos:[14,4,22],state:15},{pos:[12,4,22],state:15},{pos:[9,4,22],state:4},{pos:[8,4,22],state:17},{pos:[7,4,22],state:17},{pos:[6,4,22],state:4},{pos:[20,5,22],state:14},{pos:[17,5,22],state:14},{pos:[14,5,22],state:15},{pos:[13,5,22],state:6},{pos:[12,5,22],state:15},{pos:[9,5,22],state:14},{pos:[6,5,22],state:14},{pos:[13,6,22],state:0},{pos:[14,7,22],state:6},{pos:[13,7,22],state:4},{pos:[12,7,22],state:6},{pos:[13,8,22],state:0},{pos:[13,9,22],state:6},{pos:[13,10,22],state:12},{pos:[13,11,22],state:0},{pos:[14,12,22],state:4},{pos:[13,12,22],state:6},{pos:[12,12,22],state:4},{pos:[14,13,22],state:4},{pos:[13,13,22],state:6},{pos:[12,13,22],state:4},{pos:[14,14,22],state:18},{pos:[13,14,22],state:18},{pos:[12,14,22],state:18},{pos:[15,15,22],state:18},{pos:[14,15,22],state:18},{pos:[13,15,22],state:18},{pos:[12,15,22],state:18},{pos:[11,15,22],state:18},{pos:[15,16,22],state:18},{pos:[14,16,22],state:18},{pos:[13,16,22],state:18},{pos:[12,16,22],state:18},{pos:[11,16,22],state:18},{pos:[15,17,22],state:18},{pos:[14,17,22],state:18},{pos:[13,17,22],state:18},{pos:[12,17,22],state:18},{pos:[11,17,22],state:18},{pos:[14,18,22],state:18},{pos:[13,18,22],state:18},{pos:[12,18,22],state:18},{pos:[14,19,22],state:4},{pos:[12,19,22],state:4},{pos:[14,20,22],state:4},{pos:[12,20,22],state:4},{pos:[23,22,22],state:5},{pos:[3,22,22],state:5},{pos:[13,25,22],state:4},{pos:[13,26,22],state:6},{pos:[23,0,21],state:3},{pos:[22,0,21],state:6},{pos:[21,0,21],state:6},{pos:[16,0,21],state:6},{pos:[10,0,21],state:6},{pos:[5,0,21],state:6},{pos:[4,0,21],state:6},{pos:[3,0,21],state:3},{pos:[20,1,21],state:6},{pos:[19,1,21],state:3},{pos:[18,1,21],state:3},{pos:[17,1,21],state:6},{pos:[15,1,21],state:6},{pos:[11,1,21],state:6},{pos:[9,1,21],state:6},{pos:[8,1,21],state:3},{pos:[7,1,21],state:3},{pos:[6,1,21],state:6},{pos:[20,2,21],state:4},{pos:[19,2,21],state:3},{pos:[18,2,21],state:3},{pos:[17,2,21],state:4},{pos:[15,2,21],state:4},{pos:[11,2,21],state:4},{pos:[9,2,21],state:4},{pos:[8,2,21],state:3},{pos:[7,2,21],state:3},{pos:[6,2,21],state:4},{pos:[20,3,21],state:4},{pos:[19,3,21],state:3},{pos:[18,3,21],state:3},{pos:[17,3,21],state:4},{pos:[14,3,21],state:4},{pos:[13,3,21],state:13},{pos:[12,3,21],state:4},{pos:[9,3,21],state:4},{pos:[8,3,21],state:3},{pos:[7,3,21],state:3},{pos:[6,3,21],state:4},{pos:[20,4,21],state:17},{pos:[17,4,21],state:17},{pos:[14,4,21],state:15},{pos:[12,4,21],state:15},{pos:[9,4,21],state:17},{pos:[6,4,21],state:17},{pos:[13,5,21],state:0},{pos:[13,6,21],state:4},{pos:[13,9,21],state:6},{pos:[13,10,21],state:6},{pos:[14,11,21],state:4},{pos:[13,11,21],state:6},{pos:[12,11,21],state:4},{pos:[14,12,21],state:18},{pos:[13,12,21],state:18},{pos:[12,12,21],state:18},{pos:[15,13,21],state:18},{pos:[14,13,21],state:18},{pos:[13,13,21],state:18},{pos:[12,13,21],state:18},{pos:[11,13,21],state:18},{pos:[16,14,21],state:18},{pos:[15,14,21],state:18},{pos:[14,14,21],state:18},{pos:[13,14,21],state:18},{pos:[12,14,21],state:18},{pos:[11,14,21],state:18},{pos:[10,14,21],state:18},{pos:[17,15,21],state:18},{pos:[16,15,21],state:18},{pos:[15,15,21],state:18},{pos:[14,15,21],state:18},{pos:[13,15,21],state:18},{pos:[12,15,21],state:18},{pos:[11,15,21],state:18},{pos:[10,15,21],state:18},{pos:[9,15,21],state:18},{pos:[17,16,21],state:18},{pos:[16,16,21],state:18},{pos:[15,16,21],state:18},{pos:[14,16,21],state:18},{pos:[13,16,21],state:18},{pos:[12,16,21],state:18},{pos:[11,16,21],state:18},{pos:[10,16,21],state:18},{pos:[9,16,21],state:18},{pos:[17,17,21],state:18},{pos:[16,17,21],state:18},{pos:[15,17,21],state:18},{pos:[14,17,21],state:18},{pos:[13,17,21],state:18},{pos:[12,17,21],state:18},{pos:[11,17,21],state:18},{pos:[10,17,21],state:18},{pos:[9,17,21],state:18},{pos:[16,18,21],state:18},{pos:[15,18,21],state:18},{pos:[14,18,21],state:18},{pos:[13,18,21],state:18},{pos:[12,18,21],state:18},{pos:[11,18,21],state:18},{pos:[10,18,21],state:18},{pos:[15,19,21],state:18},{pos:[14,19,21],state:18},{pos:[13,19,21],state:18},{pos:[12,19,21],state:18},{pos:[11,19,21],state:18},{pos:[14,20,21],state:18},{pos:[13,20,21],state:18},{pos:[12,20,21],state:18},{pos:[24,21,21],state:11},{pos:[14,21,21],state:4},{pos:[12,21,21],state:4},{pos:[2,21,21],state:11},{pos:[13,25,21],state:6},{pos:[13,26,21],state:4},{pos:[13,27,21],state:6},{pos:[23,0,20],state:3},{pos:[22,0,20],state:6},{pos:[21,0,20],state:6},{pos:[16,0,20],state:6},{pos:[10,0,20],state:6},{pos:[5,0,20],state:6},{pos:[4,0,20],state:6},{pos:[3,0,20],state:3},{pos:[20,1,20],state:6},{pos:[17,1,20],state:6},{pos:[15,1,20],state:6},{pos:[11,1,20],state:6},{pos:[9,1,20],state:6},{pos:[6,1,20],state:6},{pos:[20,2,20],state:6},{pos:[17,2,20],state:6},{pos:[15,2,20],state:4},{pos:[11,2,20],state:4},{pos:[9,2,20],state:6},{pos:[6,2,20],state:6},{pos:[20,3,20],state:4},{pos:[19,3,20],state:4},{pos:[18,3,20],state:4},{pos:[17,3,20],state:4},{pos:[14,3,20],state:4},{pos:[13,3,20],state:13},{pos:[12,3,20],state:4},{pos:[9,3,20],state:4},{pos:[8,3,20],state:4},{pos:[7,3,20],state:4},{pos:[6,3,20],state:4},{pos:[15,4,20],state:15},{pos:[14,4,20],state:15},{pos:[13,4,20],state:15},{pos:[12,4,20],state:15},{pos:[11,4,20],state:15},{pos:[13,5,20],state:4},{pos:[14,10,20],state:4},{pos:[13,10,20],state:6},{pos:[12,10,20],state:4},{pos:[14,11,20],state:18},{pos:[13,11,20],state:18},{pos:[12,11,20],state:18},{pos:[16,12,20],state:18},{pos:[15,12,20],state:18},{pos:[14,12,20],state:18},{pos:[13,12,20],state:18},{pos:[12,12,20],state:18},{pos:[11,12,20],state:18},{pos:[10,12,20],state:18},{pos:[17,13,20],state:18},{pos:[16,13,20],state:18},{pos:[15,13,20],state:18},{pos:[14,13,20],state:18},{pos:[13,13,20],state:18},{pos:[12,13,20],state:18},{pos:[11,13,20],state:18},{pos:[10,13,20],state:18},{pos:[9,13,20],state:18},{pos:[17,14,20],state:18},{pos:[16,14,20],state:18},{pos:[15,14,20],state:18},{pos:[14,14,20],state:18},{pos:[13,14,20],state:18},{pos:[12,14,20],state:18},{pos:[11,14,20],state:18},{pos:[10,14,20],state:18},{pos:[9,14,20],state:18},{pos:[18,15,20],state:18},{pos:[17,15,20],state:18},{pos:[16,15,20],state:18},{pos:[15,15,20],state:18},{pos:[14,15,20],state:18},{pos:[13,15,20],state:18},{pos:[12,15,20],state:18},{pos:[11,15,20],state:18},{pos:[10,15,20],state:18},{pos:[9,15,20],state:18},{pos:[8,15,20],state:18},{pos:[18,16,20],state:18},{pos:[17,16,20],state:18},{pos:[16,16,20],state:18},{pos:[15,16,20],state:18},{pos:[14,16,20],state:18},{pos:[13,16,20],state:18},{pos:[12,16,20],state:18},{pos:[11,16,20],state:18},{pos:[10,16,20],state:18},{pos:[9,16,20],state:18},{pos:[8,16,20],state:18},{pos:[18,17,20],state:18},{pos:[17,17,20],state:18},{pos:[16,17,20],state:18},{pos:[15,17,20],state:18},{pos:[14,17,20],state:18},{pos:[13,17,20],state:18},{pos:[12,17,20],state:18},{pos:[11,17,20],state:18},{pos:[10,17,20],state:18},{pos:[9,17,20],state:18},{pos:[8,17,20],state:18},{pos:[17,18,20],state:18},{pos:[16,18,20],state:18},{pos:[15,18,20],state:18},{pos:[14,18,20],state:18},{pos:[13,18,20],state:18},{pos:[12,18,20],state:18},{pos:[11,18,20],state:18},{pos:[10,18,20],state:18},{pos:[9,18,20],state:18},{pos:[17,19,20],state:18},{pos:[16,19,20],state:18},{pos:[15,19,20],state:18},{pos:[14,19,20],state:18},{pos:[13,19,20],state:18},{pos:[12,19,20],state:18},{pos:[11,19,20],state:18},{pos:[10,19,20],state:18},{pos:[9,19,20],state:18},{pos:[24,20,20],state:11},{pos:[16,20,20],state:18},{pos:[15,20,20],state:18},{pos:[14,20,20],state:18},{pos:[13,20,20],state:18},{pos:[12,20,20],state:18},{pos:[11,20,20],state:18},{pos:[10,20,20],state:18},{pos:[1,20,20],state:11},{pos:[14,21,20],state:18},{pos:[13,21,20],state:18},{pos:[12,21,20],state:18},{pos:[14,22,20],state:4},{pos:[12,22,20],state:4},{pos:[13,25,20],state:6},{pos:[13,26,20],state:4},{pos:[13,27,20],state:6},{pos:[23,0,19],state:3},{pos:[22,0,19],state:6},{pos:[21,0,19],state:6},{pos:[5,0,19],state:6},{pos:[4,0,19],state:6},{pos:[3,0,19],state:3},{pos:[20,1,19],state:8},{pos:[19,1,19],state:6},{pos:[18,1,19],state:6},{pos:[17,1,19],state:6},{pos:[16,1,19],state:6},{pos:[15,1,19],state:6},{pos:[11,1,19],state:6},{pos:[10,1,19],state:6},{pos:[9,1,19],state:6},{pos:[8,1,19],state:6},{pos:[7,1,19],state:4},{pos:[6,1,19],state:8},{pos:[20,2,19],state:14},{pos:[19,2,19],state:4},{pos:[18,2,19],state:4},{pos:[17,2,19],state:4},{pos:[16,2,19],state:4},{pos:[15,2,19],state:4},{pos:[11,2,19],state:4},{pos:[10,2,19],state:4},{pos:[9,2,19],state:4},{pos:[8,2,19],state:4},{pos:[7,2,19],state:4},{pos:[6,2,19],state:14},{pos:[19,3,19],state:4},{pos:[18,3,19],state:4},{pos:[14,3,19],state:4},{pos:[13,3,19],state:13},{pos:[12,3,19],state:4},{pos:[8,3,19],state:4},{pos:[7,3,19],state:4},{pos:[16,4,19],state:15},{pos:[10,4,19],state:15},{pos:[14,10,19],state:4},{pos:[13,10,19],state:6},{pos:[12,10,19],state:4},{pos:[15,11,19],state:18},{pos:[14,11,19],state:18},{pos:[13,11,19],state:18},{pos:[12,11,19],state:18},{pos:[11,11,19],state:18},{pos:[17,12,19],state:18},{pos:[16,12,19],state:18},{pos:[15,12,19],state:18},{pos:[14,12,19],state:18},{pos:[13,12,19],state:18},{pos:[12,12,19],state:18},{pos:[11,12,19],state:18},{pos:[10,12,19],state:18},{pos:[9,12,19],state:18},{pos:[17,13,19],state:18},{pos:[16,13,19],state:18},{pos:[15,13,19],state:18},{pos:[14,13,19],state:18},{pos:[13,13,19],state:18},{pos:[12,13,19],state:18},{pos:[11,13,19],state:18},{pos:[10,13,19],state:18},{pos:[9,13,19],state:18},{pos:[18,14,19],state:18},{pos:[17,14,19],state:18},{pos:[16,14,19],state:18},{pos:[15,14,19],state:18},{pos:[14,14,19],state:18},{pos:[13,14,19],state:18},{pos:[12,14,19],state:18},{pos:[11,14,19],state:18},{pos:[10,14,19],state:18},{pos:[9,14,19],state:18},{pos:[8,14,19],state:18},{pos:[18,15,19],state:18},{pos:[17,15,19],state:18},{pos:[16,15,19],state:18},{pos:[15,15,19],state:18},{pos:[14,15,19],state:18},{pos:[13,15,19],state:18},{pos:[12,15,19],state:18},{pos:[11,15,19],state:18},{pos:[10,15,19],state:18},{pos:[9,15,19],state:18},{pos:[8,15,19],state:18},{pos:[18,16,19],state:18},{pos:[17,16,19],state:18},{pos:[16,16,19],state:18},{pos:[15,16,19],state:18},{pos:[14,16,19],state:18},{pos:[13,16,19],state:18},{pos:[12,16,19],state:18},{pos:[11,16,19],state:18},{pos:[10,16,19],state:18},{pos:[9,16,19],state:18},{pos:[8,16,19],state:18},{pos:[18,17,19],state:18},{pos:[17,17,19],state:18},{pos:[16,17,19],state:18},{pos:[15,17,19],state:18},{pos:[14,17,19],state:18},{pos:[13,17,19],state:18},{pos:[12,17,19],state:18},{pos:[11,17,19],state:18},{pos:[10,17,19],state:18},{pos:[9,17,19],state:18},{pos:[8,17,19],state:18},{pos:[18,18,19],state:18},{pos:[17,18,19],state:18},{pos:[16,18,19],state:18},{pos:[15,18,19],state:18},{pos:[14,18,19],state:18},{pos:[13,18,19],state:18},{pos:[12,18,19],state:18},{pos:[11,18,19],state:18},{pos:[10,18,19],state:18},{pos:[9,18,19],state:18},{pos:[8,18,19],state:18},{pos:[25,19,19],state:11},{pos:[17,19,19],state:18},{pos:[16,19,19],state:18},{pos:[15,19,19],state:18},{pos:[14,19,19],state:18},{pos:[13,19,19],state:18},{pos:[12,19,19],state:18},{pos:[11,19,19],state:18},{pos:[10,19,19],state:18},{pos:[9,19,19],state:18},{pos:[1,19,19],state:11},{pos:[17,20,19],state:18},{pos:[16,20,19],state:18},{pos:[15,20,19],state:18},{pos:[14,20,19],state:18},{pos:[13,20,19],state:18},{pos:[12,20,19],state:18},{pos:[11,20,19],state:18},{pos:[10,20,19],state:18},{pos:[9,20,19],state:18},{pos:[15,21,19],state:18},{pos:[14,21,19],state:18},{pos:[13,21,19],state:18},{pos:[12,21,19],state:18},{pos:[11,21,19],state:18},{pos:[14,22,19],state:4},{pos:[12,22,19],state:4},{pos:[13,26,19],state:6},{pos:[13,27,19],state:6},{pos:[23,0,18],state:3},{pos:[22,0,18],state:6},{pos:[21,0,18],state:6},{pos:[5,0,18],state:6},{pos:[4,0,18],state:6},{pos:[3,0,18],state:3},{pos:[20,1,18],state:8},{pos:[19,1,18],state:6},{pos:[15,1,18],state:6},{pos:[11,1,18],state:6},{pos:[7,1,18],state:4},{pos:[6,1,18],state:8},{pos:[20,2,18],state:14},{pos:[19,2,18],state:4},{pos:[18,2,18],state:19},{pos:[17,2,18],state:19},{pos:[16,2,18],state:4},{pos:[15,2,18],state:4},{pos:[11,2,18],state:4},{pos:[10,2,18],state:4},{pos:[9,2,18],state:19},{pos:[8,2,18],state:19},{pos:[7,2,18],state:4},{pos:[6,2,18],state:14},{pos:[19,3,18],state:16},{pos:[15,3,18],state:4},{pos:[14,3,18],state:4},{pos:[13,3,18],state:13},{pos:[12,3,18],state:4},{pos:[11,3,18],state:4},{pos:[7,3,18],state:16},{pos:[17,4,18],state:15},{pos:[15,4,18],state:4},{pos:[14,4,18],state:4},{pos:[13,4,18],state:4},{pos:[12,4,18],state:4},{pos:[11,4,18],state:4},{pos:[9,4,18],state:15},{pos:[15,5,18],state:20},{pos:[14,5,18],state:20},{pos:[13,5,18],state:20},{pos:[12,5,18],state:20},{pos:[11,5,18],state:20},{pos:[14,6,18],state:9},{pos:[12,6,18],state:9},{pos:[14,7,18],state:1},{pos:[12,7,18],state:1},{pos:[14,8,18],state:0},{pos:[12,8,18],state:0},{pos:[14,9,18],state:4},{pos:[12,9,18],state:4},{pos:[16,10,18],state:6},{pos:[15,10,18],state:6},{pos:[14,10,18],state:18},{pos:[13,10,18],state:18},{pos:[12,10,18],state:18},{pos:[11,10,18],state:6},{pos:[10,10,18],state:6},{pos:[16,11,18],state:18},{pos:[15,11,18],state:18},{pos:[14,11,18],state:18},{pos:[13,11,18],state:18},{pos:[12,11,18],state:18},{pos:[11,11,18],state:18},{pos:[10,11,18],state:18},{pos:[17,12,18],state:18},{pos:[16,12,18],state:18},{pos:[15,12,18],state:18},{pos:[14,12,18],state:18},{pos:[13,12,18],state:18},{pos:[12,12,18],state:18},{pos:[11,12,18],state:18},{pos:[10,12,18],state:18},{pos:[9,12,18],state:18},{pos:[18,13,18],state:18},{pos:[17,13,18],state:18},{pos:[16,13,18],state:18},{pos:[15,13,18],state:18},{pos:[14,13,18],state:18},{pos:[13,13,18],state:18},{pos:[12,13,18],state:18},{pos:[11,13,18],state:18},{pos:[10,13,18],state:18},{pos:[9,13,18],state:18},{pos:[8,13,18],state:18},{pos:[18,14,18],state:18},{pos:[17,14,18],state:18},{pos:[16,14,18],state:18},{pos:[15,14,18],state:18},{pos:[14,14,18],state:18},{pos:[13,14,18],state:18},{pos:[12,14,18],state:18},{pos:[11,14,18],state:18},{pos:[10,14,18],state:18},{pos:[9,14,18],state:18},{pos:[8,14,18],state:18},{pos:[19,15,18],state:18},{pos:[18,15,18],state:18},{pos:[17,15,18],state:18},{pos:[16,15,18],state:18},{pos:[15,15,18],state:18},{pos:[14,15,18],state:18},{pos:[13,15,18],state:18},{pos:[12,15,18],state:18},{pos:[11,15,18],state:18},{pos:[10,15,18],state:18},{pos:[9,15,18],state:18},{pos:[8,15,18],state:18},{pos:[7,15,18],state:18},{pos:[19,16,18],state:18},{pos:[18,16,18],state:18},{pos:[17,16,18],state:18},{pos:[16,16,18],state:18},{pos:[15,16,18],state:18},{pos:[14,16,18],state:18},{pos:[13,16,18],state:18},{pos:[12,16,18],state:18},{pos:[11,16,18],state:18},{pos:[10,16,18],state:18},{pos:[9,16,18],state:18},{pos:[8,16,18],state:18},{pos:[7,16,18],state:18},{pos:[19,17,18],state:18},{pos:[18,17,18],state:18},{pos:[17,17,18],state:18},{pos:[16,17,18],state:18},{pos:[15,17,18],state:18},{pos:[14,17,18],state:18},{pos:[13,17,18],state:18},{pos:[12,17,18],state:18},{pos:[11,17,18],state:18},{pos:[10,17,18],state:18},{pos:[9,17,18],state:18},{pos:[8,17,18],state:18},{pos:[7,17,18],state:18},{pos:[26,18,18],state:10},{pos:[18,18,18],state:18},{pos:[17,18,18],state:18},{pos:[16,18,18],state:18},{pos:[15,18,18],state:18},{pos:[14,18,18],state:18},{pos:[13,18,18],state:18},{pos:[12,18,18],state:18},{pos:[11,18,18],state:18},{pos:[10,18,18],state:18},{pos:[9,18,18],state:18},{pos:[8,18,18],state:18},{pos:[0,18,18],state:10},{pos:[18,19,18],state:18},{pos:[17,19,18],state:18},{pos:[16,19,18],state:18},{pos:[15,19,18],state:18},{pos:[14,19,18],state:18},{pos:[13,19,18],state:18},{pos:[12,19,18],state:18},{pos:[11,19,18],state:18},{pos:[10,19,18],state:18},{pos:[9,19,18],state:18},{pos:[8,19,18],state:18},{pos:[17,20,18],state:18},{pos:[16,20,18],state:18},{pos:[15,20,18],state:18},{pos:[14,20,18],state:18},{pos:[13,20,18],state:18},{pos:[12,20,18],state:18},{pos:[11,20,18],state:18},{pos:[10,20,18],state:18},{pos:[9,20,18],state:18},{pos:[16,21,18],state:18},{pos:[15,21,18],state:18},{pos:[14,21,18],state:18},{pos:[13,21,18],state:18},{pos:[12,21,18],state:18},{pos:[11,21,18],state:18},{pos:[10,21,18],state:18},{pos:[16,22,18],state:6},{pos:[15,22,18],state:6},{pos:[14,22,18],state:18},{pos:[13,22,18],state:18},{pos:[12,22,18],state:18},{pos:[11,22,18],state:6},{pos:[10,22,18],state:6},{pos:[14,23,18],state:4},{pos:[12,23,18],state:4},{pos:[13,27,18],state:6},{pos:[23,0,17],state:3},{pos:[22,0,17],state:6},{pos:[21,0,17],state:6},{pos:[5,0,17],state:6},{pos:[4,0,17],state:6},{pos:[3,0,17],state:3},{pos:[20,1,17],state:8},{pos:[19,1,17],state:6},{pos:[15,1,17],state:6},{pos:[11,1,17],state:6},{pos:[7,1,17],state:4},{pos:[6,1,17],state:8},{pos:[20,2,17],state:14},{pos:[19,2,17],state:4},{pos:[18,2,17],state:19},{pos:[17,2,17],state:19},{pos:[16,2,17],state:4},{pos:[15,2,17],state:4},{pos:[11,2,17],state:4},{pos:[10,2,17],state:4},{pos:[9,2,17],state:19},{pos:[8,2,17],state:19},{pos:[7,2,17],state:4},{pos:[6,2,17],state:14},{pos:[19,3,17],state:16},{pos:[15,3,17],state:4},{pos:[14,3,17],state:4},{pos:[13,3,17],state:13},{pos:[12,3,17],state:4},{pos:[11,3,17],state:4},{pos:[7,3,17],state:16},{pos:[17,4,17],state:15},{pos:[15,4,17],state:4},{pos:[14,4,17],state:6},{pos:[13,4,17],state:6},{pos:[12,4,17],state:6},{pos:[11,4,17],state:4},{pos:[9,4,17],state:15},{pos:[15,5,17],state:20},{pos:[11,5,17],state:20},{pos:[14,9,17],state:4},{pos:[12,9,17],state:4},{pos:[16,10,17],state:6},{pos:[15,10,17],state:18},{pos:[14,10,17],state:18},{pos:[13,10,17],state:18},{pos:[12,10,17],state:18},{pos:[11,10,17],state:18},{pos:[10,10,17],state:6},{pos:[17,11,17],state:18},{pos:[16,11,17],state:18},{pos:[15,11,17],state:18},{pos:[14,11,17],state:18},{pos:[13,11,17],state:18},{pos:[12,11,17],state:18},{pos:[11,11,17],state:18},{pos:[10,11,17],state:18},{pos:[9,11,17],state:18},{pos:[18,12,17],state:18},{pos:[17,12,17],state:18},{pos:[16,12,17],state:18},{pos:[15,12,17],state:18},{pos:[14,12,17],state:18},{pos:[13,12,17],state:18},{pos:[12,12,17],state:18},{pos:[11,12,17],state:18},{pos:[10,12,17],state:18},{pos:[9,12,17],state:18},{pos:[8,12,17],state:18},{pos:[18,13,17],state:18},{pos:[17,13,17],state:18},{pos:[16,13,17],state:18},{pos:[15,13,17],state:18},{pos:[14,13,17],state:18},{pos:[13,13,17],state:18},{pos:[12,13,17],state:18},{pos:[11,13,17],state:18},{pos:[10,13,17],state:18},{pos:[9,13,17],state:18},{pos:[8,13,17],state:18},{pos:[19,14,17],state:18},{pos:[18,14,17],state:18},{pos:[17,14,17],state:18},{pos:[16,14,17],state:18},{pos:[15,14,17],state:18},{pos:[14,14,17],state:18},{pos:[13,14,17],state:18},{pos:[12,14,17],state:18},{pos:[11,14,17],state:18},{pos:[10,14,17],state:18},{pos:[9,14,17],state:18},{pos:[8,14,17],state:18},{pos:[7,14,17],state:18},{pos:[19,15,17],state:18},{pos:[18,15,17],state:18},{pos:[17,15,17],state:18},{pos:[16,15,17],state:18},{pos:[15,15,17],state:18},{pos:[14,15,17],state:18},{pos:[13,15,17],state:18},{pos:[12,15,17],state:18},{pos:[11,15,17],state:18},{pos:[10,15,17],state:18},{pos:[9,15,17],state:18},{pos:[8,15,17],state:18},{pos:[7,15,17],state:18},{pos:[19,16,17],state:21},{pos:[18,16,17],state:18},{pos:[17,16,17],state:18},{pos:[16,16,17],state:18},{pos:[15,16,17],state:18},{pos:[14,16,17],state:18},{pos:[13,16,17],state:18},{pos:[12,16,17],state:18},{pos:[11,16,17],state:18},{pos:[10,16,17],state:18},{pos:[9,16,17],state:18},{pos:[8,16,17],state:18},{pos:[7,16,17],state:21},{pos:[26,17,17],state:10},{pos:[19,17,17],state:18},{pos:[18,17,17],state:18},{pos:[17,17,17],state:18},{pos:[16,17,17],state:18},{pos:[15,17,17],state:18},{pos:[14,17,17],state:18},{pos:[13,17,17],state:18},{pos:[12,17,17],state:18},{pos:[11,17,17],state:18},{pos:[10,17,17],state:18},{pos:[9,17,17],state:18},{pos:[8,17,17],state:18},{pos:[7,17,17],state:18},{pos:[0,17,17],state:10},{pos:[19,18,17],state:18},{pos:[18,18,17],state:18},{pos:[17,18,17],state:18},{pos:[16,18,17],state:18},{pos:[15,18,17],state:18},{pos:[14,18,17],state:18},{pos:[13,18,17],state:18},{pos:[12,18,17],state:18},{pos:[11,18,17],state:18},{pos:[10,18,17],state:18},{pos:[9,18,17],state:18},{pos:[8,18,17],state:18},{pos:[7,18,17],state:18},{pos:[18,19,17],state:18},{pos:[17,19,17],state:18},{pos:[16,19,17],state:18},{pos:[15,19,17],state:18},{pos:[14,19,17],state:18},{pos:[13,19,17],state:18},{pos:[12,19,17],state:18},{pos:[11,19,17],state:18},{pos:[10,19,17],state:18},{pos:[9,19,17],state:18},{pos:[8,19,17],state:18},{pos:[18,20,17],state:18},{pos:[17,20,17],state:18},{pos:[16,20,17],state:18},{pos:[15,20,17],state:18},{pos:[14,20,17],state:18},{pos:[13,20,17],state:18},{pos:[12,20,17],state:18},{pos:[11,20,17],state:18},{pos:[10,20,17],state:18},{pos:[9,20,17],state:18},{pos:[8,20,17],state:18},{pos:[17,21,17],state:18},{pos:[16,21,17],state:18},{pos:[15,21,17],state:18},{pos:[14,21,17],state:18},{pos:[13,21,17],state:18},{pos:[12,21,17],state:18},{pos:[11,21,17],state:18},{pos:[10,21,17],state:18},{pos:[9,21,17],state:18},{pos:[16,22,17],state:6},{pos:[15,22,17],state:18},{pos:[14,22,17],state:18},{pos:[13,22,17],state:18},{pos:[12,22,17],state:18},{pos:[11,22,17],state:18},{pos:[10,22,17],state:6},{pos:[14,23,17],state:4},{pos:[12,23,17],state:4},{pos:[13,27,17],state:6},{pos:[23,0,16],state:3},{pos:[22,0,16],state:6},{pos:[21,0,16],state:6},{pos:[5,0,16],state:6},{pos:[4,0,16],state:6},{pos:[3,0,16],state:3},{pos:[20,1,16],state:8},{pos:[19,1,16],state:6},{pos:[15,1,16],state:6},{pos:[11,1,16],state:6},{pos:[7,1,16],state:4},{pos:[6,1,16],state:8},{pos:[20,2,16],state:14},{pos:[19,2,16],state:4},{pos:[18,2,16],state:19},{pos:[17,2,16],state:19},{pos:[16,2,16],state:4},{pos:[15,2,16],state:4},{pos:[11,2,16],state:4},{pos:[10,2,16],state:4},{pos:[9,2,16],state:19},{pos:[8,2,16],state:19},{pos:[7,2,16],state:4},{pos:[6,2,16],state:14},{pos:[19,3,16],state:16},{pos:[15,3,16],state:4},{pos:[14,3,16],state:4},{pos:[13,3,16],state:13},{pos:[12,3,16],state:4},{pos:[11,3,16],state:4},{pos:[7,3,16],state:16},{pos:[17,4,16],state:15},{pos:[15,4,16],state:4},{pos:[14,4,16],state:6},{pos:[13,4,16],state:13},{pos:[12,4,16],state:6},{pos:[11,4,16],state:4},{pos:[9,4,16],state:15},{pos:[15,5,16],state:20},{pos:[11,5,16],state:20},{pos:[14,8,16],state:4},{pos:[13,8,16],state:4},{pos:[12,8,16],state:4},{pos:[14,9,16],state:4},{pos:[12,9,16],state:4},{pos:[16,10,16],state:6},{pos:[15,10,16],state:18},{pos:[14,10,16],state:18},{pos:[13,10,16],state:18},{pos:[12,10,16],state:18},{pos:[11,10,16],state:18},{pos:[10,10,16],state:6},{pos:[17,11,16],state:18},{pos:[16,11,16],state:18},{pos:[15,11,16],state:18},{pos:[14,11,16],state:18},{pos:[13,11,16],state:18},{pos:[12,11,16],state:18},{pos:[11,11,16],state:18},{pos:[10,11,16],state:18},{pos:[9,11,16],state:18},{pos:[18,12,16],state:18},{pos:[17,12,16],state:18},{pos:[16,12,16],state:18},{pos:[15,12,16],state:18},{pos:[14,12,16],state:18},{pos:[13,12,16],state:18},{pos:[12,12,16],state:18},{pos:[11,12,16],state:18},{pos:[10,12,16],state:18},{pos:[9,12,16],state:18},{pos:[8,12,16],state:18},{pos:[18,13,16],state:18},{pos:[17,13,16],state:18},{pos:[16,13,16],state:18},{pos:[15,13,16],state:18},{pos:[14,13,16],state:18},{pos:[13,13,16],state:18},{pos:[12,13,16],state:18},{pos:[11,13,16],state:18},{pos:[10,13,16],state:18},{pos:[9,13,16],state:18},{pos:[8,13,16],state:18},{pos:[19,14,16],state:18},{pos:[18,14,16],state:18},{pos:[17,14,16],state:18},{pos:[16,14,16],state:18},{pos:[15,14,16],state:18},{pos:[14,14,16],state:18},{pos:[13,14,16],state:18},{pos:[12,14,16],state:18},{pos:[11,14,16],state:18},{pos:[10,14,16],state:18},{pos:[9,14,16],state:18},{pos:[8,14,16],state:18},{pos:[7,14,16],state:18},{pos:[19,15,16],state:21},{pos:[18,15,16],state:18},{pos:[17,15,16],state:18},{pos:[16,15,16],state:18},{pos:[15,15,16],state:18},{pos:[14,15,16],state:18},{pos:[13,15,16],state:18},{pos:[12,15,16],state:18},{pos:[11,15,16],state:18},{pos:[10,15,16],state:18},{pos:[9,15,16],state:18},{pos:[8,15,16],state:18},{pos:[7,15,16],state:21},{pos:[26,16,16],state:22},{pos:[25,16,16],state:23},{pos:[24,16,16],state:23},{pos:[23,16,16],state:23},{pos:[22,16,16],state:23},{pos:[21,16,16],state:23},{pos:[20,16,16],state:23},{pos:[19,16,16],state:22},{pos:[18,16,16],state:18},{pos:[17,16,16],state:18},{pos:[16,16,16],state:18},{pos:[15,16,16],state:18},{pos:[14,16,16],state:18},{pos:[13,16,16],state:18},{pos:[12,16,16],state:18},{pos:[11,16,16],state:18},{pos:[10,16,16],state:18},{pos:[9,16,16],state:18},{pos:[8,16,16],state:18},{pos:[7,16,16],state:22},{pos:[6,16,16],state:23},{pos:[5,16,16],state:23},{pos:[4,16,16],state:23},{pos:[3,16,16],state:23},{pos:[2,16,16],state:23},{pos:[1,16,16],state:23},{pos:[0,16,16],state:22},{pos:[19,17,16],state:21},{pos:[18,17,16],state:18},{pos:[17,17,16],state:18},{pos:[16,17,16],state:18},{pos:[15,17,16],state:18},{pos:[14,17,16],state:18},{pos:[13,17,16],state:18},{pos:[12,17,16],state:18},{pos:[11,17,16],state:18},{pos:[10,17,16],state:18},{pos:[9,17,16],state:18},{pos:[8,17,16],state:18},{pos:[7,17,16],state:21},{pos:[19,18,16],state:18},{pos:[18,18,16],state:18},{pos:[17,18,16],state:18},{pos:[16,18,16],state:18},{pos:[15,18,16],state:18},{pos:[14,18,16],state:18},{pos:[13,18,16],state:18},{pos:[12,18,16],state:18},{pos:[11,18,16],state:18},{pos:[10,18,16],state:18},{pos:[9,18,16],state:18},{pos:[8,18,16],state:18},{pos:[7,18,16],state:18},{pos:[18,19,16],state:18},{pos:[17,19,16],state:18},{pos:[16,19,16],state:18},{pos:[15,19,16],state:18},{pos:[14,19,16],state:18},{pos:[13,19,16],state:18},{pos:[12,19,16],state:18},{pos:[11,19,16],state:18},{pos:[10,19,16],state:18},{pos:[9,19,16],state:18},{pos:[8,19,16],state:18},{pos:[18,20,16],state:18},{pos:[17,20,16],state:18},{pos:[16,20,16],state:18},{pos:[15,20,16],state:18},{pos:[14,20,16],state:18},{pos:[13,20,16],state:18},{pos:[12,20,16],state:18},{pos:[11,20,16],state:18},{pos:[10,20,16],state:18},{pos:[9,20,16],state:18},{pos:[8,20,16],state:18},{pos:[17,21,16],state:18},{pos:[16,21,16],state:18},{pos:[15,21,16],state:18},{pos:[14,21,16],state:18},{pos:[13,21,16],state:18},{pos:[12,21,16],state:18},{pos:[11,21,16],state:18},{pos:[10,21,16],state:18},{pos:[9,21,16],state:18},{pos:[16,22,16],state:6},{pos:[15,22,16],state:18},{pos:[14,22,16],state:18},{pos:[13,22,16],state:18},{pos:[12,22,16],state:18},{pos:[11,22,16],state:18},{pos:[10,22,16],state:6},{pos:[14,23,16],state:4},{pos:[12,23,16],state:4},{pos:[14,24,16],state:17},{pos:[12,24,16],state:17},{pos:[24,0,15],state:3},{pos:[23,0,15],state:3},{pos:[22,0,15],state:6},{pos:[21,0,15],state:6},{pos:[5,0,15],state:6},{pos:[4,0,15],state:6},{pos:[3,0,15],state:3},{pos:[2,0,15],state:3},{pos:[20,1,15],state:8},{pos:[19,1,15],state:6},{pos:[15,1,15],state:6},{pos:[11,1,15],state:6},{pos:[7,1,15],state:4},{pos:[6,1,15],state:8},{pos:[20,2,15],state:14},{pos:[19,2,15],state:4},{pos:[18,2,15],state:4},{pos:[17,2,15],state:4},{pos:[16,2,15],state:4},{pos:[15,2,15],state:4},{pos:[11,2,15],state:4},{pos:[10,2,15],state:4},{pos:[9,2,15],state:4},{pos:[8,2,15],state:4},{pos:[7,2,15],state:4},{pos:[6,2,15],state:14},{pos:[19,3,15],state:16},{pos:[17,3,15],state:15},{pos:[15,3,15],state:4},{pos:[14,3,15],state:4},{pos:[13,3,15],state:13},{pos:[12,3,15],state:4},{pos:[11,3,15],state:4},{pos:[9,3,15],state:15},{pos:[7,3,15],state:16},{pos:[17,4,15],state:15},{pos:[15,4,15],state:4},{pos:[14,4,15],state:6},{pos:[13,4,15],state:6},{pos:[12,4,15],state:6},{pos:[11,4,15],state:4},{pos:[9,4,15],state:15},{pos:[15,5,15],state:20},{pos:[11,5,15],state:20},{pos:[14,7,15],state:4},{pos:[13,7,15],state:4},{pos:[12,7,15],state:4},{pos:[14,8,15],state:4},{pos:[13,8,15],state:7},{pos:[12,8,15],state:4},{pos:[14,9,15],state:4},{pos:[13,9,15],state:4},{pos:[12,9,15],state:4},{pos:[16,10,15],state:6},{pos:[15,10,15],state:18},{pos:[14,10,15],state:18},{pos:[13,10,15],state:18},{pos:[12,10,15],state:18},{pos:[11,10,15],state:18},{pos:[10,10,15],state:6},{pos:[17,11,15],state:18},{pos:[16,11,15],state:18},{pos:[15,11,15],state:18},{pos:[14,11,15],state:18},{pos:[13,11,15],state:18},{pos:[12,11,15],state:18},{pos:[11,11,15],state:18},{pos:[10,11,15],state:18},{pos:[9,11,15],state:18},{pos:[18,12,15],state:18},{pos:[17,12,15],state:18},{pos:[16,12,15],state:18},{pos:[15,12,15],state:18},{pos:[14,12,15],state:18},{pos:[13,12,15],state:18},{pos:[12,12,15],state:18},{pos:[11,12,15],state:18},{pos:[10,12,15],state:18},{pos:[9,12,15],state:18},{pos:[8,12,15],state:18},{pos:[18,13,15],state:18},{pos:[17,13,15],state:18},{pos:[16,13,15],state:18},{pos:[15,13,15],state:18},{pos:[14,13,15],state:18},{pos:[13,13,15],state:18},{pos:[12,13,15],state:18},{pos:[11,13,15],state:18},{pos:[10,13,15],state:18},{pos:[9,13,15],state:18},{pos:[8,13,15],state:18},{pos:[19,14,15],state:18},{pos:[18,14,15],state:18},{pos:[17,14,15],state:18},{pos:[16,14,15],state:18},{pos:[15,14,15],state:18},{pos:[14,14,15],state:18},{pos:[13,14,15],state:18},{pos:[12,14,15],state:18},{pos:[11,14,15],state:18},{pos:[10,14,15],state:18},{pos:[9,14,15],state:18},{pos:[8,14,15],state:18},{pos:[7,14,15],state:18},{pos:[26,15,15],state:10},{pos:[19,15,15],state:18},{pos:[18,15,15],state:18},{pos:[17,15,15],state:18},{pos:[16,15,15],state:18},{pos:[15,15,15],state:18},{pos:[14,15,15],state:18},{pos:[13,15,15],state:18},{pos:[12,15,15],state:18},{pos:[11,15,15],state:18},{pos:[10,15,15],state:18},{pos:[9,15,15],state:18},{pos:[8,15,15],state:18},{pos:[7,15,15],state:18},{pos:[0,15,15],state:10},{pos:[19,16,15],state:21},{pos:[18,16,15],state:18},{pos:[17,16,15],state:18},{pos:[16,16,15],state:18},{pos:[15,16,15],state:18},{pos:[14,16,15],state:18},{pos:[13,16,15],state:18},{pos:[12,16,15],state:18},{pos:[11,16,15],state:18},{pos:[10,16,15],state:18},{pos:[9,16,15],state:18},{pos:[8,16,15],state:18},{pos:[7,16,15],state:21},{pos:[19,17,15],state:18},{pos:[18,17,15],state:18},{pos:[17,17,15],state:18},{pos:[16,17,15],state:18},{pos:[15,17,15],state:18},{pos:[14,17,15],state:18},{pos:[13,17,15],state:18},{pos:[12,17,15],state:18},{pos:[11,17,15],state:18},{pos:[10,17,15],state:18},{pos:[9,17,15],state:18},{pos:[8,17,15],state:18},{pos:[7,17,15],state:18},{pos:[19,18,15],state:18},{pos:[18,18,15],state:18},{pos:[17,18,15],state:18},{pos:[16,18,15],state:18},{pos:[15,18,15],state:18},{pos:[14,18,15],state:18},{pos:[13,18,15],state:18},{pos:[12,18,15],state:18},{pos:[11,18,15],state:18},{pos:[10,18,15],state:18},{pos:[9,18,15],state:18},{pos:[8,18,15],state:18},{pos:[7,18,15],state:18},{pos:[18,19,15],state:18},{pos:[17,19,15],state:18},{pos:[16,19,15],state:18},{pos:[15,19,15],state:18},{pos:[14,19,15],state:18},{pos:[13,19,15],state:18},{pos:[12,19,15],state:18},{pos:[11,19,15],state:18},{pos:[10,19,15],state:18},{pos:[9,19,15],state:18},{pos:[8,19,15],state:18},{pos:[18,20,15],state:18},{pos:[17,20,15],state:18},{pos:[16,20,15],state:18},{pos:[15,20,15],state:18},{pos:[14,20,15],state:18},{pos:[13,20,15],state:18},{pos:[12,20,15],state:18},{pos:[11,20,15],state:18},{pos:[10,20,15],state:18},{pos:[9,20,15],state:18},{pos:[8,20,15],state:18},{pos:[17,21,15],state:18},{pos:[16,21,15],state:18},{pos:[15,21,15],state:18},{pos:[14,21,15],state:18},{pos:[13,21,15],state:18},{pos:[12,21,15],state:18},{pos:[11,21,15],state:18},{pos:[10,21,15],state:18},{pos:[9,21,15],state:18},{pos:[16,22,15],state:6},{pos:[15,22,15],state:18},{pos:[14,22,15],state:18},{pos:[13,22,15],state:18},{pos:[12,22,15],state:18},{pos:[11,22,15],state:18},{pos:[10,22,15],state:6},{pos:[14,23,15],state:4},{pos:[12,23,15],state:4},{pos:[14,24,15],state:17},{pos:[12,24,15],state:17},{pos:[24,0,14],state:3},{pos:[23,0,14],state:6},{pos:[22,0,14],state:6},{pos:[21,0,14],state:6},{pos:[5,0,14],state:6},{pos:[4,0,14],state:6},{pos:[3,0,14],state:6},{pos:[2,0,14],state:3},{pos:[24,1,14],state:0},{pos:[20,1,14],state:8},{pos:[19,1,14],state:6},{pos:[18,1,14],state:6},{pos:[17,1,14],state:6},{pos:[16,1,14],state:6},{pos:[15,1,14],state:6},{pos:[14,1,14],state:6},{pos:[13,1,14],state:13},{pos:[12,1,14],state:6},{pos:[11,1,14],state:6},{pos:[10,1,14],state:6},{pos:[9,1,14],state:6},{pos:[8,1,14],state:6},{pos:[7,1,14],state:4},{pos:[6,1,14],state:8},{pos:[2,1,14],state:0},{pos:[20,2,14],state:14},{pos:[19,2,14],state:4},{pos:[18,2,14],state:4},{pos:[17,2,14],state:4},{pos:[16,2,14],state:4},{pos:[15,2,14],state:4},{pos:[14,2,14],state:4},{pos:[13,2,14],state:13},{pos:[12,2,14],state:4},{pos:[11,2,14],state:4},{pos:[10,2,14],state:4},{pos:[9,2,14],state:4},{pos:[8,2,14],state:4},{pos:[7,2,14],state:4},{pos:[6,2,14],state:14},{pos:[19,3,14],state:16},{pos:[17,3,14],state:15},{pos:[15,3,14],state:4},{pos:[14,3,14],state:4},{pos:[13,3,14],state:13},{pos:[12,3,14],state:4},{pos:[11,3,14],state:4},{pos:[9,3,14],state:15},{pos:[7,3,14],state:16},{pos:[15,4,14],state:4},{pos:[14,4,14],state:4},{pos:[13,4,14],state:4},{pos:[12,4,14],state:4},{pos:[11,4,14],state:4},{pos:[15,5,14],state:20},{pos:[14,5,14],state:20},{pos:[13,5,14],state:20},{pos:[12,5,14],state:20},{pos:[11,5,14],state:20},{pos:[14,6,14],state:4},{pos:[13,6,14],state:4},{pos:[12,6,14],state:4},{pos:[14,7,14],state:4},{pos:[13,7,14],state:7},{pos:[12,7,14],state:4},{pos:[14,8,14],state:24},{pos:[13,8,14],state:7},{pos:[12,8,14],state:24},{pos:[14,9,14],state:4},{pos:[13,9,14],state:25},{pos:[12,9,14],state:4},{pos:[16,10,14],state:6},{pos:[15,10,14],state:6},{pos:[14,10,14],state:18},{pos:[13,10,14],state:18},{pos:[12,10,14],state:18},{pos:[11,10,14],state:6},{pos:[10,10,14],state:6},{pos:[16,11,14],state:18},{pos:[15,11,14],state:18},{pos:[14,11,14],state:18},{pos:[13,11,14],state:18},{pos:[12,11,14],state:18},{pos:[11,11,14],state:18},{pos:[10,11,14],state:18},{pos:[17,12,14],state:18},{pos:[16,12,14],state:18},{pos:[15,12,14],state:18},{pos:[14,12,14],state:18},{pos:[13,12,14],state:18},{pos:[12,12,14],state:18},{pos:[11,12,14],state:18},{pos:[10,12,14],state:18},{pos:[9,12,14],state:18},{pos:[18,13,14],state:18},{pos:[17,13,14],state:18},{pos:[16,13,14],state:18},{pos:[15,13,14],state:18},{pos:[14,13,14],state:18},{pos:[13,13,14],state:18},{pos:[12,13,14],state:18},{pos:[11,13,14],state:18},{pos:[10,13,14],state:18},{pos:[9,13,14],state:18},{pos:[8,13,14],state:18},{pos:[26,14,14],state:10},{pos:[18,14,14],state:18},{pos:[17,14,14],state:18},{pos:[16,14,14],state:18},{pos:[15,14,14],state:18},{pos:[14,14,14],state:18},{pos:[13,14,14],state:18},{pos:[12,14,14],state:18},{pos:[11,14,14],state:18},{pos:[10,14,14],state:18},{pos:[9,14,14],state:18},{pos:[8,14,14],state:18},{pos:[0,14,14],state:10},{pos:[19,15,14],state:18},{pos:[18,15,14],state:18},{pos:[17,15,14],state:18},{pos:[16,15,14],state:18},{pos:[15,15,14],state:18},{pos:[14,15,14],state:18},{pos:[13,15,14],state:18},{pos:[12,15,14],state:18},{pos:[11,15,14],state:18},{pos:[10,15,14],state:18},{pos:[9,15,14],state:18},{pos:[8,15,14],state:18},{pos:[7,15,14],state:18},{pos:[19,16,14],state:18},{pos:[18,16,14],state:18},{pos:[17,16,14],state:18},{pos:[16,16,14],state:18},{pos:[15,16,14],state:18},{pos:[14,16,14],state:18},{pos:[13,16,14],state:18},{pos:[12,16,14],state:18},{pos:[11,16,14],state:18},{pos:[10,16,14],state:18},{pos:[9,16,14],state:18},{pos:[8,16,14],state:18},{pos:[7,16,14],state:18},{pos:[19,17,14],state:18},{pos:[18,17,14],state:18},{pos:[17,17,14],state:18},{pos:[16,17,14],state:18},{pos:[15,17,14],state:18},{pos:[14,17,14],state:18},{pos:[13,17,14],state:18},{pos:[12,17,14],state:18},{pos:[11,17,14],state:18},{pos:[10,17,14],state:18},{pos:[9,17,14],state:18},{pos:[8,17,14],state:18},{pos:[7,17,14],state:18},{pos:[18,18,14],state:18},{pos:[17,18,14],state:18},{pos:[16,18,14],state:18},{pos:[15,18,14],state:18},{pos:[14,18,14],state:18},{pos:[13,18,14],state:18},{pos:[12,18,14],state:18},{pos:[11,18,14],state:18},{pos:[10,18,14],state:18},{pos:[9,18,14],state:18},{pos:[8,18,14],state:18},{pos:[18,19,14],state:18},{pos:[17,19,14],state:18},{pos:[16,19,14],state:18},{pos:[15,19,14],state:18},{pos:[14,19,14],state:18},{pos:[13,19,14],state:18},{pos:[12,19,14],state:18},{pos:[11,19,14],state:18},{pos:[10,19,14],state:18},{pos:[9,19,14],state:18},{pos:[8,19,14],state:18},{pos:[17,20,14],state:18},{pos:[16,20,14],state:18},{pos:[15,20,14],state:18},{pos:[14,20,14],state:18},{pos:[13,20,14],state:18},{pos:[12,20,14],state:18},{pos:[11,20,14],state:18},{pos:[10,20,14],state:18},{pos:[9,20,14],state:18},{pos:[16,21,14],state:18},{pos:[15,21,14],state:18},{pos:[14,21,14],state:18},{pos:[13,21,14],state:18},{pos:[12,21,14],state:18},{pos:[11,21,14],state:18},{pos:[10,21,14],state:18},{pos:[16,22,14],state:6},{pos:[15,22,14],state:6},{pos:[14,22,14],state:18},{pos:[13,22,14],state:18},{pos:[12,22,14],state:18},{pos:[11,22,14],state:6},{pos:[10,22,14],state:6},{pos:[14,23,14],state:4},{pos:[12,23,14],state:4},{pos:[14,24,14],state:17},{pos:[12,24,14],state:17},{pos:[24,0,13],state:3},{pos:[23,0,13],state:6},{pos:[22,0,13],state:6},{pos:[21,0,13],state:6},{pos:[18,0,13],state:6},{pos:[17,0,13],state:6},{pos:[16,0,13],state:6},{pos:[10,0,13],state:6},{pos:[9,0,13],state:6},{pos:[8,0,13],state:6},{pos:[5,0,13],state:6},{pos:[4,0,13],state:6},{pos:[3,0,13],state:6},{pos:[2,0,13],state:3},{pos:[20,1,13],state:8},{pos:[19,1,13],state:6},{pos:[15,1,13],state:6},{pos:[14,1,13],state:13},{pos:[13,1,13],state:13},{pos:[12,1,13],state:13},{pos:[11,1,13],state:6},{pos:[7,1,13],state:4},{pos:[6,1,13],state:8},{pos:[20,2,13],state:14},{pos:[19,2,13],state:4},{pos:[15,2,13],state:6},{pos:[14,2,13],state:4},{pos:[12,2,13],state:4},{pos:[11,2,13],state:6},{pos:[7,2,13],state:4},{pos:[6,2,13],state:14},{pos:[19,3,13],state:16},{pos:[14,3,13],state:4},{pos:[12,3,13],state:4},{pos:[7,3,13],state:16},{pos:[14,4,13],state:4},{pos:[12,4,13],state:4},{pos:[14,5,13],state:4},{pos:[13,5,13],state:15},{pos:[12,5,13],state:4},{pos:[14,6,13],state:4},{pos:[13,6,13],state:7},{pos:[12,6,13],state:4},{pos:[14,7,13],state:24},{pos:[13,7,13],state:7},{pos:[12,7,13],state:24},{pos:[14,8,13],state:24},{pos:[13,8,13],state:7},{pos:[12,8,13],state:24},{pos:[14,9,13],state:4},{pos:[13,9,13],state:24},{pos:[12,9,13],state:4},{pos:[14,10,13],state:4},{pos:[12,10,13],state:4},{pos:[15,11,13],state:18},{pos:[14,11,13],state:18},{pos:[13,11,13],state:18},{pos:[12,11,13],state:18},{pos:[11,11,13],state:18},{pos:[17,12,13],state:18},{pos:[16,12,13],state:18},{pos:[15,12,13],state:18},{pos:[14,12,13],state:18},{pos:[13,12,13],state:18},{pos:[12,12,13],state:18},{pos:[11,12,13],state:18},{pos:[10,12,13],state:18},{pos:[9,12,13],state:18},{pos:[25,13,13],state:11},{pos:[17,13,13],state:18},{pos:[16,13,13],state:18},{pos:[15,13,13],state:18},{pos:[14,13,13],state:18},{pos:[13,13,13],state:18},{pos:[12,13,13],state:18},{pos:[11,13,13],state:18},{pos:[10,13,13],state:18},{pos:[9,13,13],state:18},{pos:[1,13,13],state:11},{pos:[18,14,13],state:18},{pos:[17,14,13],state:18},{pos:[16,14,13],state:18},{pos:[15,14,13],state:18},{pos:[14,14,13],state:18},{pos:[13,14,13],state:18},{pos:[12,14,13],state:18},{pos:[11,14,13],state:18},{pos:[10,14,13],state:18},{pos:[9,14,13],state:18},{pos:[8,14,13],state:18},{pos:[18,15,13],state:18},{pos:[17,15,13],state:18},{pos:[16,15,13],state:18},{pos:[15,15,13],state:18},{pos:[14,15,13],state:18},{pos:[13,15,13],state:18},{pos:[12,15,13],state:18},{pos:[11,15,13],state:18},{pos:[10,15,13],state:18},{pos:[9,15,13],state:18},{pos:[8,15,13],state:18},{pos:[18,16,13],state:18},{pos:[17,16,13],state:18},{pos:[16,16,13],state:18},{pos:[15,16,13],state:18},{pos:[14,16,13],state:18},{pos:[13,16,13],state:18},{pos:[12,16,13],state:18},{pos:[11,16,13],state:18},{pos:[10,16,13],state:18},{pos:[9,16,13],state:18},{pos:[8,16,13],state:18},{pos:[18,17,13],state:18},{pos:[17,17,13],state:18},{pos:[16,17,13],state:18},{pos:[15,17,13],state:18},{pos:[14,17,13],state:18},{pos:[13,17,13],state:18},{pos:[12,17,13],state:18},{pos:[11,17,13],state:18},{pos:[10,17,13],state:18},{pos:[9,17,13],state:18},{pos:[8,17,13],state:18},{pos:[18,18,13],state:18},{pos:[17,18,13],state:18},{pos:[16,18,13],state:18},{pos:[15,18,13],state:18},{pos:[14,18,13],state:18},{pos:[13,18,13],state:18},{pos:[12,18,13],state:18},{pos:[11,18,13],state:18},{pos:[10,18,13],state:18},{pos:[9,18,13],state:18},{pos:[8,18,13],state:18},{pos:[17,19,13],state:18},{pos:[16,19,13],state:18},{pos:[15,19,13],state:18},{pos:[14,19,13],state:18},{pos:[13,19,13],state:18},{pos:[12,19,13],state:18},{pos:[11,19,13],state:18},{pos:[10,19,13],state:18},{pos:[9,19,13],state:18},{pos:[17,20,13],state:18},{pos:[16,20,13],state:18},{pos:[15,20,13],state:18},{pos:[14,20,13],state:18},{pos:[13,20,13],state:18},{pos:[12,20,13],state:18},{pos:[11,20,13],state:18},{pos:[10,20,13],state:18},{pos:[9,20,13],state:18},{pos:[15,21,13],state:18},{pos:[14,21,13],state:18},{pos:[13,21,13],state:18},{pos:[12,21,13],state:18},{pos:[11,21,13],state:18},{pos:[14,22,13],state:4},{pos:[12,22,13],state:4},{pos:[14,23,13],state:17},{pos:[12,23,13],state:17},{pos:[14,24,13],state:17},{pos:[12,24,13],state:17},{pos:[24,0,12],state:3},{pos:[23,0,12],state:6},{pos:[18,0,12],state:6},{pos:[17,0,12],state:6},{pos:[16,0,12],state:6},{pos:[10,0,12],state:6},{pos:[9,0,12],state:6},{pos:[8,0,12],state:6},{pos:[3,0,12],state:6},{pos:[2,0,12],state:3},{pos:[22,1,12],state:6},{pos:[21,1,12],state:6},{pos:[20,1,12],state:6},{pos:[19,1,12],state:13},{pos:[18,1,12],state:13},{pos:[17,1,12],state:13},{pos:[16,1,12],state:13},{pos:[15,1,12],state:13},{pos:[14,1,12],state:13},{pos:[12,1,12],state:13},{pos:[11,1,12],state:13},{pos:[10,1,12],state:13},{pos:[9,1,12],state:13},{pos:[8,1,12],state:13},{pos:[7,1,12],state:13},{pos:[6,1,12],state:6},{pos:[5,1,12],state:6},{pos:[4,1,12],state:6},{pos:[22,2,12],state:17},{pos:[21,2,12],state:4},{pos:[20,2,12],state:4},{pos:[19,2,12],state:4},{pos:[15,2,12],state:6},{pos:[14,2,12],state:4},{pos:[12,2,12],state:4},{pos:[11,2,12],state:6},{pos:[7,2,12],state:4},{pos:[6,2,12],state:4},{pos:[5,2,12],state:4},{pos:[4,2,12],state:17},{pos:[20,3,12],state:17},{pos:[19,3,12],state:4},{pos:[18,3,12],state:17},{pos:[17,3,12],state:17},{pos:[16,3,12],state:14},{pos:[15,3,12],state:17},{pos:[14,3,12],state:4},{pos:[12,3,12],state:4},{pos:[11,3,12],state:17},{pos:[10,3,12],state:14},{pos:[9,3,12],state:17},{pos:[8,3,12],state:17},{pos:[7,3,12],state:4},{pos:[6,3,12],state:17},{pos:[14,4,12],state:4},{pos:[13,4,12],state:15},{pos:[12,4,12],state:4},{pos:[14,5,12],state:4},{pos:[13,5,12],state:7},{pos:[12,5,12],state:4},{pos:[14,6,12],state:24},{pos:[13,6,12],state:7},{pos:[12,6,12],state:24},{pos:[14,7,12],state:24},{pos:[13,7,12],state:7},{pos:[12,7,12],state:24},{pos:[14,8,12],state:4},{pos:[13,8,12],state:24},{pos:[12,8,12],state:4},{pos:[14,9,12],state:4},{pos:[12,9,12],state:4},{pos:[14,10,12],state:4},{pos:[12,10,12],state:4},{pos:[14,11,12],state:18},{pos:[13,11,12],state:18},{pos:[12,11,12],state:18},{pos:[25,12,12],state:11},{pos:[16,12,12],state:18},{pos:[15,12,12],state:18},{pos:[14,12,12],state:18},{pos:[13,12,12],state:18},{pos:[12,12,12],state:18},{pos:[11,12,12],state:18},{pos:[10,12,12],state:18},{pos:[1,12,12],state:11},{pos:[17,13,12],state:18},{pos:[16,13,12],state:18},{pos:[15,13,12],state:18},{pos:[14,13,12],state:18},{pos:[13,13,12],state:18},{pos:[12,13,12],state:18},{pos:[11,13,12],state:18},{pos:[10,13,12],state:18},{pos:[9,13,12],state:18},{pos:[17,14,12],state:18},{pos:[16,14,12],state:18},{pos:[15,14,12],state:18},{pos:[14,14,12],state:18},{pos:[13,14,12],state:18},{pos:[12,14,12],state:18},{pos:[11,14,12],state:18},{pos:[10,14,12],state:18},{pos:[9,14,12],state:18},{pos:[18,15,12],state:18},{pos:[17,15,12],state:18},{pos:[16,15,12],state:18},{pos:[15,15,12],state:18},{pos:[14,15,12],state:18},{pos:[13,15,12],state:18},{pos:[12,15,12],state:18},{pos:[11,15,12],state:18},{pos:[10,15,12],state:18},{pos:[9,15,12],state:18},{pos:[8,15,12],state:18},{pos:[18,16,12],state:18},{pos:[17,16,12],state:18},{pos:[16,16,12],state:18},{pos:[15,16,12],state:18},{pos:[14,16,12],state:18},{pos:[13,16,12],state:18},{pos:[12,16,12],state:18},{pos:[11,16,12],state:18},{pos:[10,16,12],state:18},{pos:[9,16,12],state:18},{pos:[8,16,12],state:18},{pos:[18,17,12],state:18},{pos:[17,17,12],state:18},{pos:[16,17,12],state:18},{pos:[15,17,12],state:18},{pos:[14,17,12],state:18},{pos:[13,17,12],state:18},{pos:[12,17,12],state:18},{pos:[11,17,12],state:18},{pos:[10,17,12],state:18},{pos:[9,17,12],state:18},{pos:[8,17,12],state:18},{pos:[17,18,12],state:18},{pos:[16,18,12],state:18},{pos:[15,18,12],state:18},{pos:[14,18,12],state:18},{pos:[13,18,12],state:18},{pos:[12,18,12],state:18},{pos:[11,18,12],state:18},{pos:[10,18,12],state:18},{pos:[9,18,12],state:18},{pos:[17,19,12],state:18},{pos:[16,19,12],state:18},{pos:[15,19,12],state:18},{pos:[14,19,12],state:18},{pos:[13,19,12],state:18},{pos:[12,19,12],state:18},{pos:[11,19,12],state:18},{pos:[10,19,12],state:18},{pos:[15,20,12],state:18},{pos:[14,20,12],state:18},{pos:[13,20,12],state:18},{pos:[12,20,12],state:18},{pos:[11,20,12],state:18},{pos:[14,21,12],state:18},{pos:[13,21,12],state:18},{pos:[12,21,12],state:18},{pos:[14,22,12],state:4},{pos:[12,22,12],state:4},{pos:[14,23,12],state:26},{pos:[12,23,12],state:17},{pos:[14,24,12],state:26},{pos:[12,24,12],state:17},{pos:[24,0,11],state:3},{pos:[23,0,11],state:6},{pos:[22,0,11],state:6},{pos:[18,0,11],state:6},{pos:[17,0,11],state:6},{pos:[16,0,11],state:6},{pos:[10,0,11],state:6},{pos:[9,0,11],state:6},{pos:[8,0,11],state:6},{pos:[4,0,11],state:6},{pos:[3,0,11],state:6},{pos:[2,0,11],state:3},{pos:[21,1,11],state:22},{pos:[20,1,11],state:6},{pos:[19,1,11],state:13},{pos:[15,1,11],state:13},{pos:[14,1,11],state:4},{pos:[12,1,11],state:4},{pos:[11,1,11],state:13},{pos:[7,1,11],state:13},{pos:[6,1,11],state:6},{pos:[5,1,11],state:22},{pos:[21,2,11],state:17},{pos:[20,2,11],state:4},{pos:[19,2,11],state:4},{pos:[15,2,11],state:6},{pos:[14,2,11],state:4},{pos:[12,2,11],state:4},{pos:[11,2,11],state:6},{pos:[7,2,11],state:4},{pos:[6,2,11],state:4},{pos:[5,2,11],state:17},{pos:[19,3,11],state:16},{pos:[14,3,11],state:4},{pos:[13,3,11],state:15},{pos:[12,3,11],state:4},{pos:[7,3,11],state:16},{pos:[14,4,11],state:4},{pos:[13,4,11],state:7},{pos:[12,4,11],state:4},{pos:[14,5,11],state:24},{pos:[13,5,11],state:7},{pos:[12,5,11],state:24},{pos:[14,6,11],state:24},{pos:[13,6,11],state:7},{pos:[12,6,11],state:24},{pos:[14,7,11],state:4},{pos:[13,7,11],state:24},{pos:[12,7,11],state:4},{pos:[14,8,11],state:17},{pos:[12,8,11],state:17},{pos:[14,10,11],state:4},{pos:[12,10,11],state:4},{pos:[24,11,11],state:11},{pos:[14,11,11],state:4},{pos:[12,11,11],state:4},{pos:[2,11,11],state:11},{pos:[14,12,11],state:18},{pos:[13,12,11],state:18},{pos:[12,12,11],state:18},{pos:[15,13,11],state:18},{pos:[14,13,11],state:18},{pos:[13,13,11],state:18},{pos:[12,13,11],state:18},{pos:[11,13,11],state:18},{pos:[16,14,11],state:18},{pos:[15,14,11],state:18},{pos:[14,14,11],state:18},{pos:[13,14,11],state:18},{pos:[12,14,11],state:18},{pos:[11,14,11],state:18},{pos:[10,14,11],state:18},{pos:[17,15,11],state:18},{pos:[16,15,11],state:18},{pos:[15,15,11],state:18},{pos:[14,15,11],state:18},{pos:[13,15,11],state:18},{pos:[12,15,11],state:18},{pos:[11,15,11],state:18},{pos:[10,15,11],state:18},{pos:[9,15,11],state:18},{pos:[17,16,11],state:18},{pos:[16,16,11],state:18},{pos:[15,16,11],state:18},{pos:[14,16,11],state:18},{pos:[13,16,11],state:18},{pos:[12,16,11],state:18},{pos:[11,16,11],state:18},{pos:[10,16,11],state:18},{pos:[9,16,11],state:18},{pos:[17,17,11],state:18},{pos:[16,17,11],state:18},{pos:[15,17,11],state:18},{pos:[14,17,11],state:18},{pos:[13,17,11],state:18},{pos:[12,17,11],state:18},{pos:[11,17,11],state:18},{pos:[10,17,11],state:18},{pos:[9,17,11],state:18},{pos:[16,18,11],state:18},{pos:[15,18,11],state:18},{pos:[14,18,11],state:18},{pos:[13,18,11],state:18},{pos:[12,18,11],state:18},{pos:[11,18,11],state:18},{pos:[10,18,11],state:18},{pos:[15,19,11],state:18},{pos:[14,19,11],state:18},{pos:[13,19,11],state:18},{pos:[12,19,11],state:18},{pos:[11,19,11],state:18},{pos:[14,20,11],state:18},{pos:[13,20,11],state:18},{pos:[12,20,11],state:18},{pos:[14,22,11],state:4},{pos:[12,22,11],state:4},{pos:[14,23,11],state:17},{pos:[12,23,11],state:17},{pos:[14,24,11],state:17},{pos:[12,24,11],state:17},{pos:[24,0,10],state:3},{pos:[23,0,10],state:6},{pos:[18,0,10],state:6},{pos:[17,0,10],state:6},{pos:[16,0,10],state:6},{pos:[15,0,10],state:6},{pos:[14,0,10],state:6},{pos:[12,0,10],state:6},{pos:[11,0,10],state:6},{pos:[10,0,10],state:6},{pos:[9,0,10],state:6},{pos:[8,0,10],state:6},{pos:[3,0,10],state:6},{pos:[2,0,10],state:3},{pos:[22,1,10],state:13},{pos:[21,1,10],state:13},{pos:[20,1,10],state:13},{pos:[19,1,10],state:13},{pos:[15,1,10],state:6},{pos:[14,1,10],state:4},{pos:[12,1,10],state:4},{pos:[11,1,10],state:6},{pos:[7,1,10],state:13},{pos:[6,1,10],state:13},{pos:[5,1,10],state:13},{pos:[4,1,10],state:13},{pos:[22,2,10],state:17},{pos:[21,2,10],state:4},{pos:[20,2,10],state:4},{pos:[19,2,10],state:4},{pos:[14,2,10],state:4},{pos:[13,2,10],state:15},{pos:[12,2,10],state:4},{pos:[7,2,10],state:4},{pos:[6,2,10],state:4},{pos:[5,2,10],state:4},{pos:[4,2,10],state:17},{pos:[20,3,10],state:17},{pos:[19,3,10],state:4},{pos:[18,3,10],state:17},{pos:[17,3,10],state:17},{pos:[16,3,10],state:14},{pos:[15,3,10],state:17},{pos:[14,3,10],state:4},{pos:[13,3,10],state:7},{pos:[12,3,10],state:4},{pos:[11,3,10],state:17},{pos:[10,3,10],state:14},{pos:[9,3,10],state:17},{pos:[8,3,10],state:17},{pos:[7,3,10],state:4},{pos:[6,3,10],state:17},{pos:[14,4,10],state:24},{pos:[13,4,10],state:7},{pos:[12,4,10],state:24},{pos:[14,5,10],state:24},{pos:[13,5,10],state:7},{pos:[12,5,10],state:24},{pos:[14,6,10],state:4},{pos:[13,6,10],state:24},{pos:[12,6,10],state:4},{pos:[14,7,10],state:17},{pos:[12,7,10],state:17},{pos:[23,10,10],state:5},{pos:[3,10,10],state:5},{pos:[14,12,10],state:4},{pos:[12,12,10],state:4},{pos:[14,13,10],state:4},{pos:[12,13,10],state:4},{pos:[14,14,10],state:18},{pos:[13,14,10],state:18},{pos:[12,14,10],state:18},{pos:[15,15,10],state:18},{pos:[14,15,10],state:18},{pos:[13,15,10],state:18},{pos:[12,15,10],state:18},{pos:[11,15,10],state:18},{pos:[15,16,10],state:18},{pos:[14,16,10],state:18},{pos:[13,16,10],state:18},{pos:[12,16,10],state:18},{pos:[11,16,10],state:18},{pos:[15,17,10],state:18},{pos:[14,17,10],state:18},{pos:[13,17,10],state:18},{pos:[12,17,10],state:18},{pos:[11,17,10],state:18},{pos:[14,18,10],state:18},{pos:[13,18,10],state:18},{pos:[12,18,10],state:18},{pos:[14,23,10],state:4},{pos:[12,23,10],state:4},{pos:[14,24,10],state:17},{pos:[12,24,10],state:17},{pos:[24,0,9],state:3},{pos:[23,0,9],state:6},{pos:[22,0,9],state:6},{pos:[21,0,9],state:6},{pos:[20,0,9],state:6},{pos:[19,0,9],state:6},{pos:[18,0,9],state:6},{pos:[17,0,9],state:14},{pos:[16,0,9],state:14},{pos:[15,0,9],state:6},{pos:[14,0,9],state:6},{pos:[13,0,9],state:15},{pos:[12,0,9],state:6},{pos:[11,0,9],state:6},{pos:[10,0,9],state:14},{pos:[9,0,9],state:14},{pos:[8,0,9],state:6},{pos:[7,0,9],state:6},{pos:[6,0,9],state:6},{pos:[5,0,9],state:6},{pos:[4,0,9],state:6},{pos:[3,0,9],state:6},{pos:[2,0,9],state:3},{pos:[14,1,9],state:4},{pos:[13,1,9],state:15},{pos:[12,1,9],state:4},{pos:[14,2,9],state:4},{pos:[13,2,9],state:7},{pos:[12,2,9],state:4},{pos:[14,3,9],state:24},{pos:[13,3,9],state:7},{pos:[12,3,9],state:24},{pos:[14,4,9],state:24},{pos:[13,4,9],state:7},{pos:[12,4,9],state:24},{pos:[14,5,9],state:4},{pos:[13,5,9],state:24},{pos:[12,5,9],state:4},{pos:[14,6,9],state:17},{pos:[12,6,9],state:17},{pos:[22,9,9],state:5},{pos:[4,9,9],state:5},{pos:[14,14,9],state:4},{pos:[12,14,9],state:4},{pos:[14,15,9],state:4},{pos:[12,15,9],state:4},{pos:[14,16,9],state:4},{pos:[12,16,9],state:4},{pos:[14,17,9],state:4},{pos:[12,17,9],state:4},{pos:[14,18,9],state:4},{pos:[12,18,9],state:4},{pos:[24,0,8],state:3},{pos:[23,0,8],state:3},{pos:[22,0,8],state:3},{pos:[21,0,8],state:6},{pos:[20,0,8],state:6},{pos:[19,0,8],state:6},{pos:[18,0,8],state:6},{pos:[17,0,8],state:14},{pos:[14,0,8],state:24},{pos:[13,0,8],state:7},{pos:[12,0,8],state:24},{pos:[9,0,8],state:14},{pos:[8,0,8],state:6},{pos:[7,0,8],state:6},{pos:[6,0,8],state:6},{pos:[5,0,8],state:6},{pos:[4,0,8],state:3},{pos:[3,0,8],state:3},{pos:[2,0,8],state:3},{pos:[24,1,8],state:0},{pos:[14,1,8],state:24},{pos:[13,1,8],state:7},{pos:[12,1,8],state:24},{pos:[2,1,8],state:0},{pos:[14,2,8],state:24},{pos:[13,2,8],state:7},{pos:[12,2,8],state:24},{pos:[14,3,8],state:24},{pos:[13,3,8],state:7},{pos:[12,3,8],state:24},{pos:[14,4,8],state:4},{pos:[13,4,8],state:24},{pos:[12,4,8],state:4},{pos:[14,5,8],state:17},{pos:[12,5,8],state:17},{pos:[21,8,8],state:5},{pos:[20,8,8],state:5},{pos:[19,8,8],state:5},{pos:[7,8,8],state:5},{pos:[6,8,8],state:5},{pos:[5,8,8],state:5},{pos:[14,15,8],state:4},{pos:[12,15,8],state:4},{pos:[14,16,8],state:17},{pos:[12,16,8],state:17},{pos:[14,18,8],state:4},{pos:[12,18,8],state:4},{pos:[14,19,8],state:17},{pos:[12,19,8],state:17},{pos:[22,0,7],state:3},{pos:[21,0,7],state:6},{pos:[20,0,7],state:6},{pos:[19,0,7],state:6},{pos:[18,0,7],state:6},{pos:[17,0,7],state:14},{pos:[14,0,7],state:6},{pos:[13,0,7],state:6},{pos:[12,0,7],state:6},{pos:[9,0,7],state:14},{pos:[8,0,7],state:6},{pos:[7,0,7],state:6},{pos:[6,0,7],state:6},{pos:[5,0,7],state:6},{pos:[4,0,7],state:3},{pos:[14,1,7],state:4},{pos:[13,1,7],state:24},{pos:[12,1,7],state:4},{pos:[14,2,7],state:4},{pos:[13,2,7],state:27},{pos:[12,2,7],state:4},{pos:[14,3,7],state:4},{pos:[13,3,7],state:24},{pos:[12,3,7],state:4},{pos:[14,4,7],state:17},{pos:[12,4,7],state:17},{pos:[18,7,7],state:11},{pos:[17,7,7],state:11},{pos:[16,7,7],state:11},{pos:[10,7,7],state:11},{pos:[9,7,7],state:11},{pos:[8,7,7],state:11},{pos:[14,16,7],state:4},{pos:[12,16,7],state:4},{pos:[14,17,7],state:4},{pos:[12,17,7],state:4},{pos:[14,18,7],state:4},{pos:[12,18,7],state:4},{pos:[14,19,7],state:17},{pos:[12,19,7],state:17},{pos:[22,0,6],state:3},{pos:[21,0,6],state:6},{pos:[20,0,6],state:6},{pos:[19,0,6],state:6},{pos:[18,0,6],state:6},{pos:[17,0,6],state:14},{pos:[14,0,6],state:0},{pos:[12,0,6],state:0},{pos:[9,0,6],state:14},{pos:[8,0,6],state:6},{pos:[7,0,6],state:6},{pos:[6,0,6],state:6},{pos:[5,0,6],state:6},{pos:[4,0,6],state:3},{pos:[14,1,6],state:28},{pos:[12,1,6],state:28},{pos:[14,2,6],state:9},{pos:[12,2,6],state:9},{pos:[14,3,6],state:28},{pos:[12,3,6],state:28},{pos:[15,6,6],state:10},{pos:[14,6,6],state:10},{pos:[13,6,6],state:10},{pos:[12,6,6],state:10},{pos:[11,6,6],state:10},{pos:[22,0,5],state:3},{pos:[21,0,5],state:6},{pos:[20,0,5],state:6},{pos:[19,0,5],state:6},{pos:[18,0,5],state:6},{pos:[17,0,5],state:14},{pos:[16,0,5],state:14},{pos:[10,0,5],state:14},{pos:[9,0,5],state:14},{pos:[8,0,5],state:6},{pos:[7,0,5],state:6},{pos:[6,0,5],state:6},{pos:[5,0,5],state:6},{pos:[4,0,5],state:3},{pos:[22,0,4],state:3},{pos:[21,0,4],state:3},{pos:[20,0,4],state:3},{pos:[19,0,4],state:3},{pos:[18,0,4],state:6},{pos:[17,0,4],state:6},{pos:[16,0,4],state:14},{pos:[15,0,4],state:14},{pos:[11,0,4],state:14},{pos:[10,0,4],state:14},{pos:[9,0,4],state:6},{pos:[8,0,4],state:6},{pos:[7,0,4],state:3},{pos:[6,0,4],state:3},{pos:[5,0,4],state:3},{pos:[4,0,4],state:3},{pos:[22,1,4],state:0},{pos:[4,1,4],state:0},{pos:[19,0,3],state:3},{pos:[18,0,3],state:3},{pos:[17,0,3],state:6},{pos:[16,0,3],state:6},{pos:[15,0,3],state:14},{pos:[14,0,3],state:14},{pos:[13,0,3],state:14},{pos:[12,0,3],state:14},{pos:[11,0,3],state:14},{pos:[10,0,3],state:6},{pos:[9,0,3],state:6},{pos:[8,0,3],state:3},{pos:[7,0,3],state:3},{pos:[19,1,3],state:0},{pos:[7,1,3],state:0},{pos:[18,0,2],state:3},{pos:[17,0,2],state:3},{pos:[16,0,2],state:6},{pos:[15,0,2],state:6},{pos:[14,0,2],state:6},{pos:[13,0,2],state:6},{pos:[12,0,2],state:6},{pos:[11,0,2],state:6},{pos:[10,0,2],state:6},{pos:[9,0,2],state:3},{pos:[8,0,2],state:3},{pos:[17,0,1],state:3},{pos:[16,0,1],state:3},{pos:[15,0,1],state:6},{pos:[14,0,1],state:6},{pos:[13,0,1],state:6},{pos:[12,0,1],state:6},{pos:[11,0,1],state:6},{pos:[10,0,1],state:3},{pos:[9,0,1],state:3},{pos:[17,1,1],state:0},{pos:[9,1,1],state:0},{pos:[16,0,0],state:3},{pos:[15,0,0],state:3},{pos:[14,0,0],state:3},{pos:[13,0,0],state:3},{pos:[12,0,0],state:3},{pos:[11,0,0],state:3},{pos:[10,0,0],state:3},{pos:[14,1,0],state:0},{pos:[12,1,0],state:0}],entities:[]}