{size:[9,8,22],palette:[{Name:"data_energistics:data_framework"},{Name:"ae2:quartz_glass"},{Name:"data_energistics:me_digital_pattern_processing_core"},{Name:"data_energistics:trinity_data_core",Properties:{"facing":"north"}},{Name:"ae2:smooth_sky_stone_slab"}],blocks:[{pos:[1,0,20],state:0},{pos:[2,0,20],state:0},{pos:[3,0,20],state:0},{pos:[4,0,20],state:0},{pos:[1,0,19],state:0},{pos:[2,0,19],state:0},{pos:[3,0,19],state:0},{pos:[4,0,19],state:0},{pos:[1,0,18],state:0},{pos:[2,0,18],state:0},{pos:[3,0,18],state:0},{pos:[4,0,18],state:0},{pos:[1,0,17],state:0},{pos:[2,0,17],state:0},{pos:[3,0,17],state:0},{pos:[4,0,17],state:0},{pos:[0,1,21],state:0},{pos:[1,1,21],state:1},{pos:[2,1,21],state:1},{pos:[3,1,21],state:1},{pos:[4,1,21],state:1},{pos:[5,1,21],state:0},{pos:[0,1,20],state:1},{pos:[1,1,20],state:2},{pos:[2,1,20],state:2},{pos:[3,1,20],state:2},{pos:[4,1,20],state:2},{pos:[5,1,20],state:1},{pos:[0,1,19],state:1},{pos:[1,1,19],state:2},{pos:[2,1,19],state:2},{pos:[3,1,19],state:2},{pos:[4,1,19],state:2},{pos:[5,1,19],state:1},{pos:[0,1,18],state:1},{pos:[1,1,18],state:2},{pos:[2,1,18],state:2},{pos:[3,1,18],state:2},{pos:[4,1,18],state:2},{pos:[5,1,18],state:1},{pos:[0,1,17],state:1},{pos:[1,1,17],state:2},{pos:[2,1,17],state:2},{pos:[3,1,17],state:2},{pos:[4,1,17],state:2},{pos:[5,1,17],state:1},{pos:[0,1,16],state:0},{pos:[5,1,16],state:0},{pos:[0,2,21],state:0},{pos:[1,2,21],state:1},{pos:[2,2,21],state:1},{pos:[3,2,21],state:1},{pos:[4,2,21],state:1},{pos:[5,2,21],state:0},{pos:[0,2,20],state:1},{pos:[1,2,20],state:2},{pos:[2,2,20],state:2},{pos:[3,2,20],state:2},{pos:[4,2,20],state:2},{pos:[5,2,20],state:1},{pos:[0,2,19],state:1},{pos:[1,2,19],state:2},{pos:[2,2,19],state:2},{pos:[3,2,19],state:2},{pos:[4,2,19],state:2},{pos:[5,2,19],state:1},{pos:[0,2,18],state:1},{pos:[1,2,18],state:2},{pos:[2,2,18],state:2},{pos:[3,2,18],state:2},{pos:[4,2,18],state:2},{pos:[5,2,18],state:1},{pos:[0,2,17],state:1},{pos:[1,2,17],state:2},{pos:[2,2,17],state:2},{pos:[3,2,17],state:2},{pos:[4,2,17],state:2},{pos:[5,2,17],state:1},{pos:[0,2,16],state:0},{pos:[5,2,16],state:0},{pos:[8,2,0],state:3},{pos:[0,3,21],state:0},{pos:[1,3,21],state:1},{pos:[2,3,21],state:1},{pos:[3,3,21],state:1},{pos:[4,3,21],state:1},{pos:[5,3,21],state:0},{pos:[0,3,20],state:1},{pos:[1,3,20],state:2},{pos:[2,3,20],state:2},{pos:[3,3,20],state:2},{pos:[4,3,20],state:2},{pos:[5,3,20],state:1},{pos:[0,3,19],state:1},{pos:[1,3,19],state:2},{pos:[2,3,19],state:2},{pos:[3,3,19],state:2},{pos:[4,3,19],state:2},{pos:[5,3,19],state:1},{pos:[0,3,18],state:1},{pos:[1,3,18],state:2},{pos:[2,3,18],state:2},{pos:[3,3,18],state:2},{pos:[4,3,18],state:2},{pos:[5,3,18],state:1},{pos:[0,3,17],state:1},{pos:[1,3,17],state:2},{pos:[2,3,17],state:2},{pos:[3,3,17],state:2},{pos:[4,3,17],state:2},{pos:[5,3,17],state:1},{pos:[0,3,16],state:0},{pos:[5,3,16],state:0},{pos:[0,4,21],state:0},{pos:[1,4,21],state:1},{pos:[2,4,21],state:1},{pos:[3,4,21],state:1},{pos:[4,4,21],state:1},{pos:[5,4,21],state:0},{pos:[0,4,20],state:1},{pos:[1,4,20],state:2},{pos:[2,4,20],state:2},{pos:[3,4,20],state:2},{pos:[4,4,20],state:2},{pos:[5,4,20],state:1},{pos:[0,4,19],state:1},{pos:[1,4,19],state:2},{pos:[2,4,19],state:2},{pos:[3,4,19],state:2},{pos:[4,4,19],state:2},{pos:[5,4,19],state:1},{pos:[0,4,18],state:1},{pos:[1,4,18],state:2},{pos:[2,4,18],state:2},{pos:[3,4,18],state:2},{pos:[4,4,18],state:2},{pos:[5,4,18],state:1},{pos:[0,4,17],state:1},{pos:[1,4,17],state:2},{pos:[2,4,17],state:2},{pos:[3,4,17],state:2},{pos:[4,4,17],state:2},{pos:[5,4,17],state:1},{pos:[0,4,16],state:0},{pos:[5,4,16],state:0},{pos:[0,5,21],state:0},{pos:[1,5,21],state:1},{pos:[2,5,21],state:1},{pos:[3,5,21],state:1},{pos:[4,5,21],state:1},{pos:[5,5,21],state:0},{pos:[0,5,20],state:1},{pos:[1,5,20],state:2},{pos:[2,5,20],state:2},{pos:[3,5,20],state:2},{pos:[4,5,20],state:2},{pos:[5,5,20],state:1},{pos:[0,5,19],state:1},{pos:[1,5,19],state:2},{pos:[2,5,19],state:2},{pos:[3,5,19],state:2},{pos:[4,5,19],state:2},{pos:[5,5,19],state:1},{pos:[0,5,18],state:1},{pos:[1,5,18],state:2},{pos:[2,5,18],state:2},{pos:[3,5,18],state:2},{pos:[4,5,18],state:2},{pos:[5,5,18],state:1},{pos:[0,5,17],state:1},{pos:[1,5,17],state:2},{pos:[2,5,17],state:2},{pos:[3,5,17],state:2},{pos:[4,5,17],state:2},{pos:[5,5,17],state:1},{pos:[0,5,16],state:0},{pos:[1,5,16],state:4},{pos:[2,5,16],state:4},{pos:[3,5,16],state:4},{pos:[4,5,16],state:4},{pos:[5,5,16],state:0},{pos:[0,6,21],state:0},{pos:[1,6,21],state:1},{pos:[2,6,21],state:1},{pos:[3,6,21],state:1},{pos:[4,6,21],state:1},{pos:[5,6,21],state:0},{pos:[0,6,20],state:1},{pos:[1,6,20],state:2},{pos:[2,6,20],state:2},{pos:[3,6,20],state:2},{pos:[4,6,20],state:2},{pos:[5,6,20],state:1},{pos:[0,6,19],state:1},{pos:[1,6,19],state:2},{pos:[2,6,19],state:2},{pos:[3,6,19],state:2},{pos:[4,6,19],state:2},{pos:[5,6,19],state:1},{pos:[0,6,18],state:1},{pos:[1,6,18],state:2},{pos:[2,6,18],state:2},{pos:[3,6,18],state:2},{pos:[4,6,18],state:2},{pos:[5,6,18],state:1},{pos:[0,6,17],state:1},{pos:[1,6,17],state:2},{pos:[2,6,17],state:2},{pos:[3,6,17],state:2},{pos:[4,6,17],state:2},{pos:[5,6,17],state:1},{pos:[0,6,16],state:0},{pos:[1,6,16],state:1},{pos:[2,6,16],state:1},{pos:[3,6,16],state:1},{pos:[4,6,16],state:1},{pos:[5,6,16],state:0},{pos:[0,7,21],state:0},{pos:[1,7,21],state:1},{pos:[2,7,21],state:1},{pos:[3,7,21],state:1},{pos:[4,7,21],state:1},{pos:[5,7,21],state:0},{pos:[0,7,20],state:1},{pos:[1,7,20],state:0},{pos:[2,7,20],state:0},{pos:[3,7,20],state:0},{pos:[4,7,20],state:0},{pos:[5,7,20],state:1},{pos:[0,7,19],state:1},{pos:[1,7,19],state:0},{pos:[2,7,19],state:0},{pos:[3,7,19],state:0},{pos:[4,7,19],state:0},{pos:[5,7,19],state:1},{pos:[0,7,18],state:1},{pos:[1,7,18],state:0},{pos:[2,7,18],state:0},{pos:[3,7,18],state:0},{pos:[4,7,18],state:0},{pos:[5,7,18],state:1},{pos:[0,7,17],state:1},{pos:[1,7,17],state:0},{pos:[2,7,17],state:0},{pos:[3,7,17],state:0},{pos:[4,7,17],state:0},{pos:[5,7,17],state:1},{pos:[0,7,16],state:0},{pos:[1,7,16],state:1},{pos:[2,7,16],state:1},{pos:[3,7,16],state:1},{pos:[4,7,16],state:1},{pos:[5,7,16],state:0}],entities:[]}