{size:[9,8,22],palette:[{Name:"data_energistics:data_framework"},{Name:"ae2:quartz_glass"},{Name:"data_energistics:me_digital_merged_storage_core_1k"},{Name:"data_energistics:trinity_data_core",Properties:{"facing":"north"}},{Name:"ae2:smooth_sky_stone_slab"}],blocks:[{pos:[4,0,20],state:0},{pos:[5,0,20],state:0},{pos:[6,0,20],state:0},{pos:[7,0,20],state:0},{pos:[4,0,19],state:0},{pos:[5,0,19],state:0},{pos:[6,0,19],state:0},{pos:[7,0,19],state:0},{pos:[4,0,18],state:0},{pos:[5,0,18],state:0},{pos:[6,0,18],state:0},{pos:[7,0,18],state:0},{pos:[4,0,17],state:0},{pos:[5,0,17],state:0},{pos:[6,0,17],state:0},{pos:[7,0,17],state:0},{pos:[3,1,21],state:0},{pos:[4,1,21],state:1},{pos:[5,1,21],state:1},{pos:[6,1,21],state:1},{pos:[7,1,21],state:1},{pos:[8,1,21],state:0},{pos:[3,1,20],state:1},{pos:[4,1,20],state:2},{pos:[5,1,20],state:2},{pos:[6,1,20],state:2},{pos:[7,1,20],state:2},{pos:[8,1,20],state:1},{pos:[3,1,19],state:1},{pos:[4,1,19],state:2},{pos:[5,1,19],state:2},{pos:[6,1,19],state:2},{pos:[7,1,19],state:2},{pos:[8,1,19],state:1},{pos:[3,1,18],state:1},{pos:[4,1,18],state:2},{pos:[5,1,18],state:2},{pos:[6,1,18],state:2},{pos:[7,1,18],state:2},{pos:[8,1,18],state:1},{pos:[3,1,17],state:1},{pos:[4,1,17],state:2},{pos:[5,1,17],state:2},{pos:[6,1,17],state:2},{pos:[7,1,17],state:2},{pos:[8,1,17],state:1},{pos:[3,1,16],state:0},{pos:[8,1,16],state:0},{pos:[3,2,21],state:0},{pos:[4,2,21],state:1},{pos:[5,2,21],state:1},{pos:[6,2,21],state:1},{pos:[7,2,21],state:1},{pos:[8,2,21],state:0},{pos:[3,2,20],state:1},{pos:[4,2,20],state:2},{pos:[5,2,20],state:2},{pos:[6,2,20],state:2},{pos:[7,2,20],state:2},{pos:[8,2,20],state:1},{pos:[3,2,19],state:1},{pos:[4,2,19],state:2},{pos:[5,2,19],state:2},{pos:[6,2,19],state:2},{pos:[7,2,19],state:2},{pos:[8,2,19],state:1},{pos:[3,2,18],state:1},{pos:[4,2,18],state:2},{pos:[5,2,18],state:2},{pos:[6,2,18],state:2},{pos:[7,2,18],state:2},{pos:[8,2,18],state:1},{pos:[3,2,17],state:1},{pos:[4,2,17],state:2},{pos:[5,2,17],state:2},{pos:[6,2,17],state:2},{pos:[7,2,17],state:2},{pos:[8,2,17],state:1},{pos:[3,2,16],state:0},{pos:[8,2,16],state:0},{pos:[0,2,0],state:3},{pos:[3,3,21],state:0},{pos:[4,3,21],state:1},{pos:[5,3,21],state:1},{pos:[6,3,21],state:1},{pos:[7,3,21],state:1},{pos:[8,3,21],state:0},{pos:[3,3,20],state:1},{pos:[4,3,20],state:2},{pos:[5,3,20],state:2},{pos:[6,3,20],state:2},{pos:[7,3,20],state:2},{pos:[8,3,20],state:1},{pos:[3,3,19],state:1},{pos:[4,3,19],state:2},{pos:[5,3,19],state:2},{pos:[6,3,19],state:2},{pos:[7,3,19],state:2},{pos:[8,3,19],state:1},{pos:[3,3,18],state:1},{pos:[4,3,18],state:2},{pos:[5,3,18],state:2},{pos:[6,3,18],state:2},{pos:[7,3,18],state:2},{pos:[8,3,18],state:1},{pos:[3,3,17],state:1},{pos:[4,3,17],state:2},{pos:[5,3,17],state:2},{pos:[6,3,17],state:2},{pos:[7,3,17],state:2},{pos:[8,3,17],state:1},{pos:[3,3,16],state:0},{pos:[8,3,16],state:0},{pos:[3,4,21],state:0},{pos:[4,4,21],state:1},{pos:[5,4,21],state:1},{pos:[6,4,21],state:1},{pos:[7,4,21],state:1},{pos:[8,4,21],state:0},{pos:[3,4,20],state:1},{pos:[4,4,20],state:2},{pos:[5,4,20],state:2},{pos:[6,4,20],state:2},{pos:[7,4,20],state:2},{pos:[8,4,20],state:1},{pos:[3,4,19],state:1},{pos:[4,4,19],state:2},{pos:[5,4,19],state:2},{pos:[6,4,19],state:2},{pos:[7,4,19],state:2},{pos:[8,4,19],state:1},{pos:[3,4,18],state:1},{pos:[4,4,18],state:2},{pos:[5,4,18],state:2},{pos:[6,4,18],state:2},{pos:[7,4,18],state:2},{pos:[8,4,18],state:1},{pos:[3,4,17],state:1},{pos:[4,4,17],state:2},{pos:[5,4,17],state:2},{pos:[6,4,17],state:2},{pos:[7,4,17],state:2},{pos:[8,4,17],state:1},{pos:[3,4,16],state:0},{pos:[8,4,16],state:0},{pos:[3,5,21],state:0},{pos:[4,5,21],state:1},{pos:[5,5,21],state:1},{pos:[6,5,21],state:1},{pos:[7,5,21],state:1},{pos:[8,5,21],state:0},{pos:[3,5,20],state:1},{pos:[4,5,20],state:2},{pos:[5,5,20],state:2},{pos:[6,5,20],state:2},{pos:[7,5,20],state:2},{pos:[8,5,20],state:1},{pos:[3,5,19],state:1},{pos:[4,5,19],state:2},{pos:[5,5,19],state:2},{pos:[6,5,19],state:2},{pos:[7,5,19],state:2},{pos:[8,5,19],state:1},{pos:[3,5,18],state:1},{pos:[4,5,18],state:2},{pos:[5,5,18],state:2},{pos:[6,5,18],state:2},{pos:[7,5,18],state:2},{pos:[8,5,18],state:1},{pos:[3,5,17],state:1},{pos:[4,5,17],state:2},{pos:[5,5,17],state:2},{pos:[6,5,17],state:2},{pos:[7,5,17],state:2},{pos:[8,5,17],state:1},{pos:[3,5,16],state:0},{pos:[4,5,16],state:4},{pos:[5,5,16],state:4},{pos:[6,5,16],state:4},{pos:[7,5,16],state:4},{pos:[8,5,16],state:0},{pos:[3,6,21],state:0},{pos:[4,6,21],state:1},{pos:[5,6,21],state:1},{pos:[6,6,21],state:1},{pos:[7,6,21],state:1},{pos:[8,6,21],state:0},{pos:[3,6,20],state:1},{pos:[4,6,20],state:2},{pos:[5,6,20],state:2},{pos:[6,6,20],state:2},{pos:[7,6,20],state:2},{pos:[8,6,20],state:1},{pos:[3,6,19],state:1},{pos:[4,6,19],state:2},{pos:[5,6,19],state:2},{pos:[6,6,19],state:2},{pos:[7,6,19],state:2},{pos:[8,6,19],state:1},{pos:[3,6,18],state:1},{pos:[4,6,18],state:2},{pos:[5,6,18],state:2},{pos:[6,6,18],state:2},{pos:[7,6,18],state:2},{pos:[8,6,18],state:1},{pos:[3,6,17],state:1},{pos:[4,6,17],state:2},{pos:[5,6,17],state:2},{pos:[6,6,17],state:2},{pos:[7,6,17],state:2},{pos:[8,6,17],state:1},{pos:[3,6,16],state:0},{pos:[4,6,16],state:1},{pos:[5,6,16],state:1},{pos:[6,6,16],state:1},{pos:[7,6,16],state:1},{pos:[8,6,16],state:0},{pos:[3,7,21],state:0},{pos:[4,7,21],state:1},{pos:[5,7,21],state:1},{pos:[6,7,21],state:1},{pos:[7,7,21],state:1},{pos:[8,7,21],state:0},{pos:[3,7,20],state:1},{pos:[4,7,20],state:0},{pos:[5,7,20],state:0},{pos:[6,7,20],state:0},{pos:[7,7,20],state:0},{pos:[8,7,20],state:1},{pos:[3,7,19],state:1},{pos:[4,7,19],state:0},{pos:[5,7,19],state:0},{pos:[6,7,19],state:0},{pos:[7,7,19],state:0},{pos:[8,7,19],state:1},{pos:[3,7,18],state:1},{pos:[4,7,18],state:0},{pos:[5,7,18],state:0},{pos:[6,7,18],state:0},{pos:[7,7,18],state:0},{pos:[8,7,18],state:1},{pos:[3,7,17],state:1},{pos:[4,7,17],state:0},{pos:[5,7,17],state:0},{pos:[6,7,17],state:0},{pos:[7,7,17],state:0},{pos:[8,7,17],state:1},{pos:[3,7,16],state:0},{pos:[4,7,16],state:1},{pos:[5,7,16],state:1},{pos:[6,7,16],state:1},{pos:[7,7,16],state:1},{pos:[8,7,16],state:0}],entities:[]}